2022-09-01 16:11:25,205 - kedro.framework.session.session - INFO - Kedro project kedro-experiment
2022-09-01 16:11:25,213 - py.warnings - WARNING - /home/anarpego/anaconda3/envs/kedro-environment/lib/python3.7/site-packages/kedro/framework/context/context.py:344: UserWarning: Credentials not found in your Kedro project config.
No files found in ['/home/anarpego/cloud_team_devops/Experiments/Cloud_Build_Kedro/kedro-experiment/conf/base', '/home/anarpego/cloud_team_devops/Experiments/Cloud_Build_Kedro/kedro-experiment/conf/local'] matching the glob pattern(s): ['credentials*', 'credentials*/**', '**/credentials*']
  warn(f"Credentials not found in your Kedro project config.\n{str(exc)}")

2022-09-01 16:11:25,288 - kedro.io.data_catalog - INFO - Loading data from 'example_iris_data' (CSVDataSet)...
2022-09-01 16:11:25,297 - kedro.io.data_catalog - INFO - Loading data from 'parameters' (MemoryDataSet)...
2022-09-01 16:11:25,299 - kedro.pipeline.node - INFO - Running node: split: split_data([example_iris_data,parameters]) -> [X_train,X_test,y_train,y_test]
2022-09-01 16:11:25,308 - kedro.io.data_catalog - INFO - Saving data to 'X_train' (MemoryDataSet)...
2022-09-01 16:11:25,310 - kedro.io.data_catalog - INFO - Saving data to 'X_test' (MemoryDataSet)...
2022-09-01 16:11:25,311 - kedro.io.data_catalog - INFO - Saving data to 'y_train' (MemoryDataSet)...
2022-09-01 16:11:25,312 - kedro.io.data_catalog - INFO - Saving data to 'y_test' (MemoryDataSet)...
2022-09-01 16:11:25,313 - kedro.runner.sequential_runner - INFO - Completed 1 out of 3 tasks
2022-09-01 16:11:25,314 - kedro.io.data_catalog - INFO - Loading data from 'X_train' (MemoryDataSet)...
2022-09-01 16:11:25,315 - kedro.io.data_catalog - INFO - Loading data from 'X_test' (MemoryDataSet)...
2022-09-01 16:11:25,316 - kedro.io.data_catalog - INFO - Loading data from 'y_train' (MemoryDataSet)...
2022-09-01 16:11:25,318 - kedro.pipeline.node - INFO - Running node: make_predictions: make_predictions([X_train,X_test,y_train]) -> [y_pred]
2022-09-01 16:11:25,319 - kedro.io.data_catalog - INFO - Saving data to 'y_pred' (MemoryDataSet)...
2022-09-01 16:11:25,320 - kedro.runner.sequential_runner - INFO - Completed 2 out of 3 tasks
2022-09-01 16:11:25,321 - kedro.io.data_catalog - INFO - Loading data from 'y_pred' (MemoryDataSet)...
2022-09-01 16:11:25,322 - kedro.io.data_catalog - INFO - Loading data from 'y_test' (MemoryDataSet)...
2022-09-01 16:11:25,323 - kedro.pipeline.node - INFO - Running node: report_accuracy: report_accuracy([y_pred,y_test]) -> None
2022-09-01 16:11:25,325 - kedro_experiment.nodes - INFO - Model has accuracy of 0.933 on test data.
2022-09-01 16:11:25,326 - kedro.runner.sequential_runner - INFO - Completed 3 out of 3 tasks
2022-09-01 16:11:25,327 - kedro.runner.sequential_runner - INFO - Pipeline execution completed successfully.
2022-09-02 09:42:54,026 - kedro.framework.session.session - INFO - Kedro project kedro-experiment
2022-09-06 11:08:27,133 - py.warnings - WARNING - /home/linuxbrew/.linuxbrew/opt/python@3.10/lib/python3.10/site-packages/kfp/v2/google/client/client.py:169: FutureWarning: AIPlatformClient will be deprecated in v2.0.0. Please use PipelineJob https://googleapis.dev/python/aiplatform/latest/_modules/google/cloud/aiplatform/pipeline_jobs.html in Vertex SDK. Install the SDK using "pip install google-cloud-aiplatform"
  warnings.warn(

2022-09-06 11:08:27,141 - py.warnings - WARNING - /home/linuxbrew/.linuxbrew/opt/python@3.10/lib/python3.10/site-packages/google/auth/_default.py:70: UserWarning: Your application has authenticated using end user credentials from Google Cloud SDK without a quota project. You might receive a "quota exceeded" or "API not enabled" error. We recommend you rerun `gcloud auth application-default login` and make sure a quota project is added. Or you can use service accounts instead. For more information about service accounts, see https://cloud.google.com/docs/authentication/
  warnings.warn(_CLOUD_SDK_CREDENTIALS_WARNING)

2022-09-06 11:08:28,297 - py.warnings - WARNING - /home/linuxbrew/.linuxbrew/opt/python@3.10/lib/python3.10/site-packages/google/auth/_default.py:70: UserWarning: Your application has authenticated using end user credentials from Google Cloud SDK without a quota project. You might receive a "quota exceeded" or "API not enabled" error. We recommend you rerun `gcloud auth application-default login` and make sure a quota project is added. Or you can use service accounts instead. For more information about service accounts, see https://cloud.google.com/docs/authentication/
  warnings.warn(_CLOUD_SDK_CREDENTIALS_WARNING)

2022-09-06 11:08:28,744 - py.warnings - WARNING - /home/linuxbrew/.linuxbrew/opt/python@3.10/lib/python3.10/site-packages/kfp/v2/compiler/compiler.py:1292: FutureWarning: APIs imported from the v1 namespace (e.g. kfp.dsl, kfp.components, etc) will not be supported by the v2 compiler since v2.0.0
  warnings.warn(

2022-09-06 11:12:12,595 - py.warnings - WARNING - /home/linuxbrew/.linuxbrew/opt/python@3.10/lib/python3.10/site-packages/kfp/v2/google/client/client.py:169: FutureWarning: AIPlatformClient will be deprecated in v2.0.0. Please use PipelineJob https://googleapis.dev/python/aiplatform/latest/_modules/google/cloud/aiplatform/pipeline_jobs.html in Vertex SDK. Install the SDK using "pip install google-cloud-aiplatform"
  warnings.warn(

2022-09-06 11:12:12,601 - py.warnings - WARNING - /home/linuxbrew/.linuxbrew/opt/python@3.10/lib/python3.10/site-packages/google/auth/_default.py:70: UserWarning: Your application has authenticated using end user credentials from Google Cloud SDK without a quota project. You might receive a "quota exceeded" or "API not enabled" error. We recommend you rerun `gcloud auth application-default login` and make sure a quota project is added. Or you can use service accounts instead. For more information about service accounts, see https://cloud.google.com/docs/authentication/
  warnings.warn(_CLOUD_SDK_CREDENTIALS_WARNING)

2022-09-06 11:12:13,172 - py.warnings - WARNING - /home/linuxbrew/.linuxbrew/opt/python@3.10/lib/python3.10/site-packages/google/auth/_default.py:70: UserWarning: Your application has authenticated using end user credentials from Google Cloud SDK without a quota project. You might receive a "quota exceeded" or "API not enabled" error. We recommend you rerun `gcloud auth application-default login` and make sure a quota project is added. Or you can use service accounts instead. For more information about service accounts, see https://cloud.google.com/docs/authentication/
  warnings.warn(_CLOUD_SDK_CREDENTIALS_WARNING)

2022-09-06 11:12:13,603 - py.warnings - WARNING - /home/linuxbrew/.linuxbrew/opt/python@3.10/lib/python3.10/site-packages/kfp/v2/compiler/compiler.py:1292: FutureWarning: APIs imported from the v1 namespace (e.g. kfp.dsl, kfp.components, etc) will not be supported by the v2 compiler since v2.0.0
  warnings.warn(

2022-09-06 11:14:07,837 - py.warnings - WARNING - /home/linuxbrew/.linuxbrew/opt/python@3.10/lib/python3.10/site-packages/kfp/v2/google/client/client.py:169: FutureWarning: AIPlatformClient will be deprecated in v2.0.0. Please use PipelineJob https://googleapis.dev/python/aiplatform/latest/_modules/google/cloud/aiplatform/pipeline_jobs.html in Vertex SDK. Install the SDK using "pip install google-cloud-aiplatform"
  warnings.warn(

2022-09-06 11:14:07,840 - py.warnings - WARNING - /home/linuxbrew/.linuxbrew/opt/python@3.10/lib/python3.10/site-packages/google/auth/_default.py:70: UserWarning: Your application has authenticated using end user credentials from Google Cloud SDK without a quota project. You might receive a "quota exceeded" or "API not enabled" error. We recommend you rerun `gcloud auth application-default login` and make sure a quota project is added. Or you can use service accounts instead. For more information about service accounts, see https://cloud.google.com/docs/authentication/
  warnings.warn(_CLOUD_SDK_CREDENTIALS_WARNING)

2022-09-06 11:14:08,242 - py.warnings - WARNING - /home/linuxbrew/.linuxbrew/opt/python@3.10/lib/python3.10/site-packages/google/auth/_default.py:70: UserWarning: Your application has authenticated using end user credentials from Google Cloud SDK without a quota project. You might receive a "quota exceeded" or "API not enabled" error. We recommend you rerun `gcloud auth application-default login` and make sure a quota project is added. Or you can use service accounts instead. For more information about service accounts, see https://cloud.google.com/docs/authentication/
  warnings.warn(_CLOUD_SDK_CREDENTIALS_WARNING)

2022-09-06 11:14:08,626 - py.warnings - WARNING - /home/linuxbrew/.linuxbrew/opt/python@3.10/lib/python3.10/site-packages/kfp/v2/compiler/compiler.py:1292: FutureWarning: APIs imported from the v1 namespace (e.g. kfp.dsl, kfp.components, etc) will not be supported by the v2 compiler since v2.0.0
  warnings.warn(

2022-09-06 11:33:10,530 - py.warnings - WARNING - /home/linuxbrew/.linuxbrew/opt/python@3.10/lib/python3.10/site-packages/kfp/v2/google/client/client.py:169: FutureWarning: AIPlatformClient will be deprecated in v2.0.0. Please use PipelineJob https://googleapis.dev/python/aiplatform/latest/_modules/google/cloud/aiplatform/pipeline_jobs.html in Vertex SDK. Install the SDK using "pip install google-cloud-aiplatform"
  warnings.warn(

2022-09-06 11:33:10,536 - py.warnings - WARNING - /home/linuxbrew/.linuxbrew/opt/python@3.10/lib/python3.10/site-packages/google/auth/_default.py:70: UserWarning: Your application has authenticated using end user credentials from Google Cloud SDK without a quota project. You might receive a "quota exceeded" or "API not enabled" error. We recommend you rerun `gcloud auth application-default login` and make sure a quota project is added. Or you can use service accounts instead. For more information about service accounts, see https://cloud.google.com/docs/authentication/
  warnings.warn(_CLOUD_SDK_CREDENTIALS_WARNING)

2022-09-06 11:33:11,297 - py.warnings - WARNING - /home/linuxbrew/.linuxbrew/opt/python@3.10/lib/python3.10/site-packages/google/auth/_default.py:70: UserWarning: Your application has authenticated using end user credentials from Google Cloud SDK without a quota project. You might receive a "quota exceeded" or "API not enabled" error. We recommend you rerun `gcloud auth application-default login` and make sure a quota project is added. Or you can use service accounts instead. For more information about service accounts, see https://cloud.google.com/docs/authentication/
  warnings.warn(_CLOUD_SDK_CREDENTIALS_WARNING)

2022-09-06 11:33:11,763 - py.warnings - WARNING - /home/linuxbrew/.linuxbrew/opt/python@3.10/lib/python3.10/site-packages/kfp/v2/compiler/compiler.py:1292: FutureWarning: APIs imported from the v1 namespace (e.g. kfp.dsl, kfp.components, etc) will not be supported by the v2 compiler since v2.0.0
  warnings.warn(

2022-09-06 12:06:35,132 - py.warnings - WARNING - /home/linuxbrew/.linuxbrew/opt/python@3.10/lib/python3.10/site-packages/google/auth/_default.py:70: UserWarning: Your application has authenticated using end user credentials from Google Cloud SDK without a quota project. You might receive a "quota exceeded" or "API not enabled" error. We recommend you rerun `gcloud auth application-default login` and make sure a quota project is added. Or you can use service accounts instead. For more information about service accounts, see https://cloud.google.com/docs/authentication/
  warnings.warn(_CLOUD_SDK_CREDENTIALS_WARNING)

2022-09-06 12:08:37,195 - root - ERROR - Failed to get healthz info attempt 1 of 5.
Traceback (most recent call last):
  File "/home/linuxbrew/.linuxbrew/opt/python@3.10/lib/python3.10/site-packages/kfp/_client.py", line 411, in get_kfp_healthz
    response = self._healthz_api.get_healthz()
  File "/home/linuxbrew/.linuxbrew/opt/python@3.10/lib/python3.10/site-packages/kfp_server_api/api/healthz_service_api.py", line 63, in get_healthz
    return self.get_healthz_with_http_info(**kwargs)  # noqa: E501
  File "/home/linuxbrew/.linuxbrew/opt/python@3.10/lib/python3.10/site-packages/kfp_server_api/api/healthz_service_api.py", line 134, in get_healthz_with_http_info
    return self.api_client.call_api(
  File "/home/linuxbrew/.linuxbrew/opt/python@3.10/lib/python3.10/site-packages/kfp_server_api/api_client.py", line 364, in call_api
    return self.__call_api(resource_path, method,
  File "/home/linuxbrew/.linuxbrew/opt/python@3.10/lib/python3.10/site-packages/kfp_server_api/api_client.py", line 188, in __call_api
    raise e
  File "/home/linuxbrew/.linuxbrew/opt/python@3.10/lib/python3.10/site-packages/kfp_server_api/api_client.py", line 181, in __call_api
    response_data = self.request(
  File "/home/linuxbrew/.linuxbrew/opt/python@3.10/lib/python3.10/site-packages/kfp_server_api/api_client.py", line 389, in request
    return self.rest_client.GET(url,
  File "/home/linuxbrew/.linuxbrew/opt/python@3.10/lib/python3.10/site-packages/kfp_server_api/rest.py", line 230, in GET
    return self.request("GET", url,
  File "/home/linuxbrew/.linuxbrew/opt/python@3.10/lib/python3.10/site-packages/kfp_server_api/rest.py", line 224, in request
    raise ApiException(http_resp=r)
kfp_server_api.exceptions.ApiException: (524)
Reason: status code 524
HTTP response headers: HTTPHeaderDict({'Content-Length': '1440', 'Content-Type': 'text/html; charset=utf-8', 'Date': 'Tue, 06 Sep 2022 18:08:37 GMT', 'Vary': 'Origin', 'X-Content-Type-Options': 'nosniff', 'X-Frame-Options': 'SAMEORIGIN', 'X-Xss-Protection': '0', 'Set-Cookie': 'S=cloud_datalab_tunnel=AhUMZyywos2t016IR5Pokb5rfUEY6gmHqXuUa-BLTs4; Path=/; Max-Age=3600', 'Alt-Svc': 'h3=":443"; ma=2592000,h3-29=":443"; ma=2592000,h3-Q050=":443"; ma=2592000,h3-Q046=":443"; ma=2592000,h3-Q043=":443"; ma=2592000,quic=":443"; ma=2592000; v="46,43"'})
HTTP response body: 
<!DOCTYPE html>
<html lang=en>
  <meta charset=utf-8>
  <meta name=viewport content="initial-scale=1, minimum-scale=1, width=device-width">
  <title>Error 524 ()!!1</title>
  <style>
    *{margin:0;padding:0}html,code{font:15px/22px arial,sans-serif}html{background:#fff;color:#222;padding:15px}body{margin:7% auto 0;max-width:390px;min-height:180px;padding:30px 0 15px}* > body{background:url(//www.google.com/images/errors/robot.png) 100% 5px no-repeat;padding-right:205px}p{margin:11px 0 22px;overflow:hidden}ins{color:#777;text-decoration:none}a img{border:0}@media screen and (max-width:772px){body{background:none;margin-top:0;max-width:none;padding-right:0}}#logo{background:url(//www.google.com/images/logos/errorpage/error_logo-150x54.png) no-repeat;margin-left:-5px}@media only screen and (min-resolution:192dpi){#logo{background:url(//www.google.com/images/logos/errorpage/error_logo-150x54-2x.png) no-repeat 0% 0%/100% 100%;-moz-border-image:url(//www.google.com/images/logos/errorpage/error_logo-150x54-2x.png) 0}}@media only screen and (-webkit-min-device-pixel-ratio:2){#logo{background:url(//www.google.com/images/logos/errorpage/error_logo-150x54-2x.png) no-repeat;-webkit-background-size:100% 100%}}#logo{display:inline-block;height:54px;width:150px}
  </style>
  <a href=//www.google.com/><span id=logo aria-label=Google></span></a>
  <p><b>524.</b> <ins>That’s an error.</ins>
  <p>  <ins>That’s all we know.</ins>


2022-09-06 12:10:42,541 - root - ERROR - Failed to get healthz info attempt 2 of 5.
Traceback (most recent call last):
  File "/home/linuxbrew/.linuxbrew/opt/python@3.10/lib/python3.10/site-packages/kfp/_client.py", line 411, in get_kfp_healthz
    response = self._healthz_api.get_healthz()
  File "/home/linuxbrew/.linuxbrew/opt/python@3.10/lib/python3.10/site-packages/kfp_server_api/api/healthz_service_api.py", line 63, in get_healthz
    return self.get_healthz_with_http_info(**kwargs)  # noqa: E501
  File "/home/linuxbrew/.linuxbrew/opt/python@3.10/lib/python3.10/site-packages/kfp_server_api/api/healthz_service_api.py", line 134, in get_healthz_with_http_info
    return self.api_client.call_api(
  File "/home/linuxbrew/.linuxbrew/opt/python@3.10/lib/python3.10/site-packages/kfp_server_api/api_client.py", line 364, in call_api
    return self.__call_api(resource_path, method,
  File "/home/linuxbrew/.linuxbrew/opt/python@3.10/lib/python3.10/site-packages/kfp_server_api/api_client.py", line 188, in __call_api
    raise e
  File "/home/linuxbrew/.linuxbrew/opt/python@3.10/lib/python3.10/site-packages/kfp_server_api/api_client.py", line 181, in __call_api
    response_data = self.request(
  File "/home/linuxbrew/.linuxbrew/opt/python@3.10/lib/python3.10/site-packages/kfp_server_api/api_client.py", line 389, in request
    return self.rest_client.GET(url,
  File "/home/linuxbrew/.linuxbrew/opt/python@3.10/lib/python3.10/site-packages/kfp_server_api/rest.py", line 230, in GET
    return self.request("GET", url,
  File "/home/linuxbrew/.linuxbrew/opt/python@3.10/lib/python3.10/site-packages/kfp_server_api/rest.py", line 224, in request
    raise ApiException(http_resp=r)
kfp_server_api.exceptions.ApiException: (524)
Reason: status code 524
HTTP response headers: HTTPHeaderDict({'Content-Length': '1440', 'Content-Type': 'text/html; charset=utf-8', 'Date': 'Tue, 06 Sep 2022 18:10:42 GMT', 'Vary': 'Origin', 'X-Content-Type-Options': 'nosniff', 'X-Frame-Options': 'SAMEORIGIN', 'X-Xss-Protection': '0', 'Set-Cookie': 'S=cloud_datalab_tunnel=AhUMZyywos2t016IR5Pokb5rfUEY6gmHqXuUa-BLTs4; Path=/; Max-Age=3600', 'Alt-Svc': 'h3=":443"; ma=2592000,h3-29=":443"; ma=2592000,h3-Q050=":443"; ma=2592000,h3-Q046=":443"; ma=2592000,h3-Q043=":443"; ma=2592000,quic=":443"; ma=2592000; v="46,43"'})
HTTP response body: 
<!DOCTYPE html>
<html lang=en>
  <meta charset=utf-8>
  <meta name=viewport content="initial-scale=1, minimum-scale=1, width=device-width">
  <title>Error 524 ()!!1</title>
  <style>
    *{margin:0;padding:0}html,code{font:15px/22px arial,sans-serif}html{background:#fff;color:#222;padding:15px}body{margin:7% auto 0;max-width:390px;min-height:180px;padding:30px 0 15px}* > body{background:url(//www.google.com/images/errors/robot.png) 100% 5px no-repeat;padding-right:205px}p{margin:11px 0 22px;overflow:hidden}ins{color:#777;text-decoration:none}a img{border:0}@media screen and (max-width:772px){body{background:none;margin-top:0;max-width:none;padding-right:0}}#logo{background:url(//www.google.com/images/logos/errorpage/error_logo-150x54.png) no-repeat;margin-left:-5px}@media only screen and (min-resolution:192dpi){#logo{background:url(//www.google.com/images/logos/errorpage/error_logo-150x54-2x.png) no-repeat 0% 0%/100% 100%;-moz-border-image:url(//www.google.com/images/logos/errorpage/error_logo-150x54-2x.png) 0}}@media only screen and (-webkit-min-device-pixel-ratio:2){#logo{background:url(//www.google.com/images/logos/errorpage/error_logo-150x54-2x.png) no-repeat;-webkit-background-size:100% 100%}}#logo{display:inline-block;height:54px;width:150px}
  </style>
  <a href=//www.google.com/><span id=logo aria-label=Google></span></a>
  <p><b>524.</b> <ins>That’s an error.</ins>
  <p>  <ins>That’s all we know.</ins>


2022-09-06 12:12:47,865 - root - ERROR - Failed to get healthz info attempt 3 of 5.
Traceback (most recent call last):
  File "/home/linuxbrew/.linuxbrew/opt/python@3.10/lib/python3.10/site-packages/kfp/_client.py", line 411, in get_kfp_healthz
    response = self._healthz_api.get_healthz()
  File "/home/linuxbrew/.linuxbrew/opt/python@3.10/lib/python3.10/site-packages/kfp_server_api/api/healthz_service_api.py", line 63, in get_healthz
    return self.get_healthz_with_http_info(**kwargs)  # noqa: E501
  File "/home/linuxbrew/.linuxbrew/opt/python@3.10/lib/python3.10/site-packages/kfp_server_api/api/healthz_service_api.py", line 134, in get_healthz_with_http_info
    return self.api_client.call_api(
  File "/home/linuxbrew/.linuxbrew/opt/python@3.10/lib/python3.10/site-packages/kfp_server_api/api_client.py", line 364, in call_api
    return self.__call_api(resource_path, method,
  File "/home/linuxbrew/.linuxbrew/opt/python@3.10/lib/python3.10/site-packages/kfp_server_api/api_client.py", line 188, in __call_api
    raise e
  File "/home/linuxbrew/.linuxbrew/opt/python@3.10/lib/python3.10/site-packages/kfp_server_api/api_client.py", line 181, in __call_api
    response_data = self.request(
  File "/home/linuxbrew/.linuxbrew/opt/python@3.10/lib/python3.10/site-packages/kfp_server_api/api_client.py", line 389, in request
    return self.rest_client.GET(url,
  File "/home/linuxbrew/.linuxbrew/opt/python@3.10/lib/python3.10/site-packages/kfp_server_api/rest.py", line 230, in GET
    return self.request("GET", url,
  File "/home/linuxbrew/.linuxbrew/opt/python@3.10/lib/python3.10/site-packages/kfp_server_api/rest.py", line 224, in request
    raise ApiException(http_resp=r)
kfp_server_api.exceptions.ApiException: (524)
Reason: status code 524
HTTP response headers: HTTPHeaderDict({'Content-Length': '1440', 'Content-Type': 'text/html; charset=utf-8', 'Date': 'Tue, 06 Sep 2022 18:12:47 GMT', 'Vary': 'Origin', 'X-Content-Type-Options': 'nosniff', 'X-Frame-Options': 'SAMEORIGIN', 'X-Xss-Protection': '0', 'Set-Cookie': 'S=cloud_datalab_tunnel=AhUMZyywos2t016IR5Pokb5rfUEY6gmHqXuUa-BLTs4; Path=/; Max-Age=3600', 'Alt-Svc': 'h3=":443"; ma=2592000,h3-29=":443"; ma=2592000,h3-Q050=":443"; ma=2592000,h3-Q046=":443"; ma=2592000,h3-Q043=":443"; ma=2592000,quic=":443"; ma=2592000; v="46,43"'})
HTTP response body: 
<!DOCTYPE html>
<html lang=en>
  <meta charset=utf-8>
  <meta name=viewport content="initial-scale=1, minimum-scale=1, width=device-width">
  <title>Error 524 ()!!1</title>
  <style>
    *{margin:0;padding:0}html,code{font:15px/22px arial,sans-serif}html{background:#fff;color:#222;padding:15px}body{margin:7% auto 0;max-width:390px;min-height:180px;padding:30px 0 15px}* > body{background:url(//www.google.com/images/errors/robot.png) 100% 5px no-repeat;padding-right:205px}p{margin:11px 0 22px;overflow:hidden}ins{color:#777;text-decoration:none}a img{border:0}@media screen and (max-width:772px){body{background:none;margin-top:0;max-width:none;padding-right:0}}#logo{background:url(//www.google.com/images/logos/errorpage/error_logo-150x54.png) no-repeat;margin-left:-5px}@media only screen and (min-resolution:192dpi){#logo{background:url(//www.google.com/images/logos/errorpage/error_logo-150x54-2x.png) no-repeat 0% 0%/100% 100%;-moz-border-image:url(//www.google.com/images/logos/errorpage/error_logo-150x54-2x.png) 0}}@media only screen and (-webkit-min-device-pixel-ratio:2){#logo{background:url(//www.google.com/images/logos/errorpage/error_logo-150x54-2x.png) no-repeat;-webkit-background-size:100% 100%}}#logo{display:inline-block;height:54px;width:150px}
  </style>
  <a href=//www.google.com/><span id=logo aria-label=Google></span></a>
  <p><b>524.</b> <ins>That’s an error.</ins>
  <p>  <ins>That’s all we know.</ins>


2022-09-06 12:14:53,113 - root - ERROR - Failed to get healthz info attempt 4 of 5.
Traceback (most recent call last):
  File "/home/linuxbrew/.linuxbrew/opt/python@3.10/lib/python3.10/site-packages/kfp/_client.py", line 411, in get_kfp_healthz
    response = self._healthz_api.get_healthz()
  File "/home/linuxbrew/.linuxbrew/opt/python@3.10/lib/python3.10/site-packages/kfp_server_api/api/healthz_service_api.py", line 63, in get_healthz
    return self.get_healthz_with_http_info(**kwargs)  # noqa: E501
  File "/home/linuxbrew/.linuxbrew/opt/python@3.10/lib/python3.10/site-packages/kfp_server_api/api/healthz_service_api.py", line 134, in get_healthz_with_http_info
    return self.api_client.call_api(
  File "/home/linuxbrew/.linuxbrew/opt/python@3.10/lib/python3.10/site-packages/kfp_server_api/api_client.py", line 364, in call_api
    return self.__call_api(resource_path, method,
  File "/home/linuxbrew/.linuxbrew/opt/python@3.10/lib/python3.10/site-packages/kfp_server_api/api_client.py", line 188, in __call_api
    raise e
  File "/home/linuxbrew/.linuxbrew/opt/python@3.10/lib/python3.10/site-packages/kfp_server_api/api_client.py", line 181, in __call_api
    response_data = self.request(
  File "/home/linuxbrew/.linuxbrew/opt/python@3.10/lib/python3.10/site-packages/kfp_server_api/api_client.py", line 389, in request
    return self.rest_client.GET(url,
  File "/home/linuxbrew/.linuxbrew/opt/python@3.10/lib/python3.10/site-packages/kfp_server_api/rest.py", line 230, in GET
    return self.request("GET", url,
  File "/home/linuxbrew/.linuxbrew/opt/python@3.10/lib/python3.10/site-packages/kfp_server_api/rest.py", line 224, in request
    raise ApiException(http_resp=r)
kfp_server_api.exceptions.ApiException: (524)
Reason: status code 524
HTTP response headers: HTTPHeaderDict({'Content-Length': '1440', 'Content-Type': 'text/html; charset=utf-8', 'Date': 'Tue, 06 Sep 2022 18:14:53 GMT', 'Vary': 'Origin', 'X-Content-Type-Options': 'nosniff', 'X-Frame-Options': 'SAMEORIGIN', 'X-Xss-Protection': '0', 'Set-Cookie': 'S=cloud_datalab_tunnel=AhUMZyywos2t016IR5Pokb5rfUEY6gmHqXuUa-BLTs4; Path=/; Max-Age=3600', 'Alt-Svc': 'h3=":443"; ma=2592000,h3-29=":443"; ma=2592000,h3-Q050=":443"; ma=2592000,h3-Q046=":443"; ma=2592000,h3-Q043=":443"; ma=2592000,quic=":443"; ma=2592000; v="46,43"'})
HTTP response body: 
<!DOCTYPE html>
<html lang=en>
  <meta charset=utf-8>
  <meta name=viewport content="initial-scale=1, minimum-scale=1, width=device-width">
  <title>Error 524 ()!!1</title>
  <style>
    *{margin:0;padding:0}html,code{font:15px/22px arial,sans-serif}html{background:#fff;color:#222;padding:15px}body{margin:7% auto 0;max-width:390px;min-height:180px;padding:30px 0 15px}* > body{background:url(//www.google.com/images/errors/robot.png) 100% 5px no-repeat;padding-right:205px}p{margin:11px 0 22px;overflow:hidden}ins{color:#777;text-decoration:none}a img{border:0}@media screen and (max-width:772px){body{background:none;margin-top:0;max-width:none;padding-right:0}}#logo{background:url(//www.google.com/images/logos/errorpage/error_logo-150x54.png) no-repeat;margin-left:-5px}@media only screen and (min-resolution:192dpi){#logo{background:url(//www.google.com/images/logos/errorpage/error_logo-150x54-2x.png) no-repeat 0% 0%/100% 100%;-moz-border-image:url(//www.google.com/images/logos/errorpage/error_logo-150x54-2x.png) 0}}@media only screen and (-webkit-min-device-pixel-ratio:2){#logo{background:url(//www.google.com/images/logos/errorpage/error_logo-150x54-2x.png) no-repeat;-webkit-background-size:100% 100%}}#logo{display:inline-block;height:54px;width:150px}
  </style>
  <a href=//www.google.com/><span id=logo aria-label=Google></span></a>
  <p><b>524.</b> <ins>That’s an error.</ins>
  <p>  <ins>That’s all we know.</ins>


2022-09-06 12:16:58,533 - root - ERROR - Failed to get healthz info attempt 5 of 5.
Traceback (most recent call last):
  File "/home/linuxbrew/.linuxbrew/opt/python@3.10/lib/python3.10/site-packages/kfp/_client.py", line 411, in get_kfp_healthz
    response = self._healthz_api.get_healthz()
  File "/home/linuxbrew/.linuxbrew/opt/python@3.10/lib/python3.10/site-packages/kfp_server_api/api/healthz_service_api.py", line 63, in get_healthz
    return self.get_healthz_with_http_info(**kwargs)  # noqa: E501
  File "/home/linuxbrew/.linuxbrew/opt/python@3.10/lib/python3.10/site-packages/kfp_server_api/api/healthz_service_api.py", line 134, in get_healthz_with_http_info
    return self.api_client.call_api(
  File "/home/linuxbrew/.linuxbrew/opt/python@3.10/lib/python3.10/site-packages/kfp_server_api/api_client.py", line 364, in call_api
    return self.__call_api(resource_path, method,
  File "/home/linuxbrew/.linuxbrew/opt/python@3.10/lib/python3.10/site-packages/kfp_server_api/api_client.py", line 188, in __call_api
    raise e
  File "/home/linuxbrew/.linuxbrew/opt/python@3.10/lib/python3.10/site-packages/kfp_server_api/api_client.py", line 181, in __call_api
    response_data = self.request(
  File "/home/linuxbrew/.linuxbrew/opt/python@3.10/lib/python3.10/site-packages/kfp_server_api/api_client.py", line 389, in request
    return self.rest_client.GET(url,
  File "/home/linuxbrew/.linuxbrew/opt/python@3.10/lib/python3.10/site-packages/kfp_server_api/rest.py", line 230, in GET
    return self.request("GET", url,
  File "/home/linuxbrew/.linuxbrew/opt/python@3.10/lib/python3.10/site-packages/kfp_server_api/rest.py", line 224, in request
    raise ApiException(http_resp=r)
kfp_server_api.exceptions.ApiException: (524)
Reason: status code 524
HTTP response headers: HTTPHeaderDict({'Content-Length': '1440', 'Content-Type': 'text/html; charset=utf-8', 'Date': 'Tue, 06 Sep 2022 18:16:58 GMT', 'Vary': 'Origin', 'X-Content-Type-Options': 'nosniff', 'X-Frame-Options': 'SAMEORIGIN', 'X-Xss-Protection': '0', 'Set-Cookie': 'S=cloud_datalab_tunnel=AhUMZyywos2t016IR5Pokb5rfUEY6gmHqXuUa-BLTs4; Path=/; Max-Age=3600', 'Alt-Svc': 'h3=":443"; ma=2592000,h3-29=":443"; ma=2592000,h3-Q050=":443"; ma=2592000,h3-Q046=":443"; ma=2592000,h3-Q043=":443"; ma=2592000,quic=":443"; ma=2592000; v="46,43"'})
HTTP response body: 
<!DOCTYPE html>
<html lang=en>
  <meta charset=utf-8>
  <meta name=viewport content="initial-scale=1, minimum-scale=1, width=device-width">
  <title>Error 524 ()!!1</title>
  <style>
    *{margin:0;padding:0}html,code{font:15px/22px arial,sans-serif}html{background:#fff;color:#222;padding:15px}body{margin:7% auto 0;max-width:390px;min-height:180px;padding:30px 0 15px}* > body{background:url(//www.google.com/images/errors/robot.png) 100% 5px no-repeat;padding-right:205px}p{margin:11px 0 22px;overflow:hidden}ins{color:#777;text-decoration:none}a img{border:0}@media screen and (max-width:772px){body{background:none;margin-top:0;max-width:none;padding-right:0}}#logo{background:url(//www.google.com/images/logos/errorpage/error_logo-150x54.png) no-repeat;margin-left:-5px}@media only screen and (min-resolution:192dpi){#logo{background:url(//www.google.com/images/logos/errorpage/error_logo-150x54-2x.png) no-repeat 0% 0%/100% 100%;-moz-border-image:url(//www.google.com/images/logos/errorpage/error_logo-150x54-2x.png) 0}}@media only screen and (-webkit-min-device-pixel-ratio:2){#logo{background:url(//www.google.com/images/logos/errorpage/error_logo-150x54-2x.png) no-repeat;-webkit-background-size:100% 100%}}#logo{display:inline-block;height:54px;width:150px}
  </style>
  <a href=//www.google.com/><span id=logo aria-label=Google></span></a>
  <p><b>524.</b> <ins>That’s an error.</ins>
  <p>  <ins>That’s all we know.</ins>


2022-09-06 14:41:14,897 - py.warnings - WARNING - /home/linuxbrew/.linuxbrew/opt/python@3.10/lib/python3.10/site-packages/kfp/v2/google/client/client.py:169: FutureWarning: AIPlatformClient will be deprecated in v2.0.0. Please use PipelineJob https://googleapis.dev/python/aiplatform/latest/_modules/google/cloud/aiplatform/pipeline_jobs.html in Vertex SDK. Install the SDK using "pip install google-cloud-aiplatform"
  warnings.warn(

2022-09-06 14:41:14,906 - py.warnings - WARNING - /home/linuxbrew/.linuxbrew/opt/python@3.10/lib/python3.10/site-packages/google/auth/_default.py:70: UserWarning: Your application has authenticated using end user credentials from Google Cloud SDK without a quota project. You might receive a "quota exceeded" or "API not enabled" error. We recommend you rerun `gcloud auth application-default login` and make sure a quota project is added. Or you can use service accounts instead. For more information about service accounts, see https://cloud.google.com/docs/authentication/
  warnings.warn(_CLOUD_SDK_CREDENTIALS_WARNING)

2022-09-06 14:41:16,416 - py.warnings - WARNING - /home/linuxbrew/.linuxbrew/opt/python@3.10/lib/python3.10/site-packages/google/auth/_default.py:70: UserWarning: Your application has authenticated using end user credentials from Google Cloud SDK without a quota project. You might receive a "quota exceeded" or "API not enabled" error. We recommend you rerun `gcloud auth application-default login` and make sure a quota project is added. Or you can use service accounts instead. For more information about service accounts, see https://cloud.google.com/docs/authentication/
  warnings.warn(_CLOUD_SDK_CREDENTIALS_WARNING)

2022-09-06 14:41:17,246 - py.warnings - WARNING - /home/linuxbrew/.linuxbrew/opt/python@3.10/lib/python3.10/site-packages/kfp/v2/compiler/compiler.py:1292: FutureWarning: APIs imported from the v1 namespace (e.g. kfp.dsl, kfp.components, etc) will not be supported by the v2 compiler since v2.0.0
  warnings.warn(

2022-09-06 14:48:27,027 - kedro.framework.session.session - INFO - Kedro project kedro-experiment
2022-09-06 14:48:27,493 - py.warnings - WARNING - /home/linuxbrew/.linuxbrew/opt/python@3.10/lib/python3.10/site-packages/kedro/framework/context/context.py:344: UserWarning: Credentials not found in your Kedro project config.
No files found in ['/home/anarpego/cloud_team_devops/Experiments/Cloud_Build_Kedro/kedro-experiment/conf/base', '/home/anarpego/cloud_team_devops/Experiments/Cloud_Build_Kedro/kedro-experiment/conf/local'] matching the glob pattern(s): ['credentials*', 'credentials*/**', '**/credentials*']
  warn(f"Credentials not found in your Kedro project config.\n{str(exc)}")

2022-09-06 14:48:27,518 - kedro.io.data_catalog - INFO - Loading data from 'example_iris_data' (CSVDataSet)...
2022-09-06 14:48:27,540 - kedro.io.data_catalog - INFO - Loading data from 'parameters' (MemoryDataSet)...
2022-09-06 14:48:27,543 - kedro.pipeline.node - INFO - Running node: split: split_data([example_iris_data,parameters]) -> [X_train,X_test,y_train,y_test]
2022-09-06 14:48:27,569 - kedro.io.data_catalog - INFO - Saving data to 'X_train' (MemoryDataSet)...
2022-09-06 14:48:27,572 - kedro.io.data_catalog - INFO - Saving data to 'X_test' (MemoryDataSet)...
2022-09-06 14:48:27,574 - kedro.io.data_catalog - INFO - Saving data to 'y_train' (MemoryDataSet)...
2022-09-06 14:48:27,575 - kedro.io.data_catalog - INFO - Saving data to 'y_test' (MemoryDataSet)...
2022-09-06 14:48:27,577 - kedro.runner.sequential_runner - INFO - Completed 1 out of 3 tasks
2022-09-06 14:48:27,578 - kedro.io.data_catalog - INFO - Loading data from 'X_train' (MemoryDataSet)...
2022-09-06 14:48:27,579 - kedro.io.data_catalog - INFO - Loading data from 'X_test' (MemoryDataSet)...
2022-09-06 14:48:27,580 - kedro.io.data_catalog - INFO - Loading data from 'y_train' (MemoryDataSet)...
2022-09-06 14:48:27,581 - kedro.pipeline.node - INFO - Running node: make_predictions: make_predictions([X_train,X_test,y_train]) -> [y_pred]
2022-09-06 14:48:27,587 - kedro.io.data_catalog - INFO - Saving data to 'y_pred' (MemoryDataSet)...
2022-09-06 14:48:27,588 - kedro.runner.sequential_runner - INFO - Completed 2 out of 3 tasks
2022-09-06 14:48:27,591 - kedro.io.data_catalog - INFO - Loading data from 'y_pred' (MemoryDataSet)...
2022-09-06 14:48:27,592 - kedro.io.data_catalog - INFO - Loading data from 'y_test' (MemoryDataSet)...
2022-09-06 14:48:27,595 - kedro.pipeline.node - INFO - Running node: report_accuracy: report_accuracy([y_pred,y_test]) -> None
2022-09-06 14:48:27,599 - kedro_experiment.nodes - INFO - Model has accuracy of 0.933 on test data.
2022-09-06 14:48:27,601 - kedro.runner.sequential_runner - INFO - Completed 3 out of 3 tasks
2022-09-06 14:48:27,602 - kedro.runner.sequential_runner - INFO - Pipeline execution completed successfully.
2022-09-06 14:49:53,600 - kedro.framework.session.session - INFO - Kedro project kedro-experiment
2022-09-06 14:51:24,985 - kedro.framework.session.session - INFO - Kedro project kedro-experiment
2022-09-06 14:51:25,227 - py.warnings - WARNING - /home/linuxbrew/.linuxbrew/opt/python@3.10/lib/python3.10/site-packages/kedro/framework/context/context.py:344: UserWarning: Credentials not found in your Kedro project config.
No files found in ['/home/anarpego/cloud_team_devops/Experiments/Cloud_Build_Kedro/kedro-experiment/conf/base', '/home/anarpego/cloud_team_devops/Experiments/Cloud_Build_Kedro/kedro-experiment/conf/local'] matching the glob pattern(s): ['credentials*', 'credentials*/**', '**/credentials*']
  warn(f"Credentials not found in your Kedro project config.\n{str(exc)}")

2022-09-06 14:51:42,687 - kedro.framework.session.session - INFO - Kedro project kedro-experiment
2022-09-06 14:52:28,743 - kedro.framework.session.session - INFO - Kedro project kedro-experiment
2022-09-06 14:52:28,995 - py.warnings - WARNING - /home/linuxbrew/.linuxbrew/opt/python@3.10/lib/python3.10/site-packages/kedro/framework/context/context.py:344: UserWarning: Credentials not found in your Kedro project config.
No files found in ['/home/anarpego/cloud_team_devops/Experiments/Cloud_Build_Kedro/kedro-experiment/conf/base', '/home/anarpego/cloud_team_devops/Experiments/Cloud_Build_Kedro/kedro-experiment/conf/local'] matching the glob pattern(s): ['credentials*', 'credentials*/**', '**/credentials*']
  warn(f"Credentials not found in your Kedro project config.\n{str(exc)}")

2022-09-06 14:52:29,003 - kedro.io.data_catalog - INFO - Loading data from 'example_iris_data' (CSVDataSet)...
2022-09-06 14:52:29,014 - kedro.io.data_catalog - INFO - Loading data from 'parameters' (MemoryDataSet)...
2022-09-06 14:52:29,016 - kedro.pipeline.node - INFO - Running node: split: split_data([example_iris_data,parameters]) -> [X_train,X_test,y_train,y_test]
2022-09-06 14:52:29,030 - kedro.io.data_catalog - INFO - Saving data to 'X_train' (MemoryDataSet)...
2022-09-06 14:52:29,032 - kedro.io.data_catalog - INFO - Saving data to 'X_test' (MemoryDataSet)...
2022-09-06 14:52:29,033 - kedro.io.data_catalog - INFO - Saving data to 'y_train' (MemoryDataSet)...
2022-09-06 14:52:29,035 - kedro.io.data_catalog - INFO - Saving data to 'y_test' (MemoryDataSet)...
2022-09-06 14:52:29,036 - kedro.runner.sequential_runner - INFO - Completed 1 out of 1 tasks
2022-09-06 14:52:29,037 - kedro.runner.sequential_runner - INFO - Pipeline execution completed successfully.
2022-09-06 14:52:29,038 - kedro.io.data_catalog - INFO - Loading data from 'y_train' (MemoryDataSet)...
2022-09-06 14:52:29,040 - kedro.io.data_catalog - INFO - Loading data from 'y_test' (MemoryDataSet)...
2022-09-06 14:52:29,041 - kedro.io.data_catalog - INFO - Loading data from 'X_test' (MemoryDataSet)...
2022-09-06 14:52:29,042 - kedro.io.data_catalog - INFO - Loading data from 'X_train' (MemoryDataSet)...
2022-09-06 14:52:43,462 - kedro.framework.session.session - INFO - Kedro project kedro-experiment
2022-09-06 14:52:43,712 - py.warnings - WARNING - /home/linuxbrew/.linuxbrew/opt/python@3.10/lib/python3.10/site-packages/kedro/framework/context/context.py:344: UserWarning: Credentials not found in your Kedro project config.
No files found in ['/home/anarpego/cloud_team_devops/Experiments/Cloud_Build_Kedro/kedro-experiment/conf/base', '/home/anarpego/cloud_team_devops/Experiments/Cloud_Build_Kedro/kedro-experiment/conf/local'] matching the glob pattern(s): ['credentials*', 'credentials*/**', '**/credentials*']
  warn(f"Credentials not found in your Kedro project config.\n{str(exc)}")

2022-09-06 15:44:51,176 - kedro.framework.session.session - INFO - Kedro project kedro-experiment
2022-09-06 15:44:51,928 - py.warnings - WARNING - /home/linuxbrew/.linuxbrew/opt/python@3.10/lib/python3.10/site-packages/kedro/framework/context/context.py:344: UserWarning: Credentials not found in your Kedro project config.
No files found in ['/home/anarpego/cloud_team_devops/Experiments/Cloud_Build_Kedro/kedro-experiment/conf/base', '/home/anarpego/cloud_team_devops/Experiments/Cloud_Build_Kedro/kedro-experiment/conf/local'] matching the glob pattern(s): ['credentials*', 'credentials*/**', '**/credentials*']
  warn(f"Credentials not found in your Kedro project config.\n{str(exc)}")

2022-09-06 15:44:51,945 - kedro.io.data_catalog - INFO - Loading data from 'example_iris_data' (CSVDataSet)...
2022-09-06 15:44:51,959 - kedro.io.data_catalog - INFO - Loading data from 'parameters' (MemoryDataSet)...
2022-09-06 15:44:51,960 - kedro.pipeline.node - INFO - Running node: split: split_data([example_iris_data,parameters]) -> [X_train,X_test,y_train,y_test]
2022-09-06 15:44:51,971 - kedro.io.data_catalog - INFO - Saving data to 'X_train' (MemoryDataSet)...
2022-09-06 15:44:51,973 - kedro.io.data_catalog - INFO - Saving data to 'X_test' (MemoryDataSet)...
2022-09-06 15:44:51,974 - kedro.io.data_catalog - INFO - Saving data to 'y_train' (MemoryDataSet)...
2022-09-06 15:44:51,976 - kedro.io.data_catalog - INFO - Saving data to 'y_test' (MemoryDataSet)...
2022-09-06 15:44:51,979 - kedro.runner.sequential_runner - INFO - Completed 1 out of 1 tasks
2022-09-06 15:44:51,982 - kedro.runner.sequential_runner - INFO - Pipeline execution completed successfully.
2022-09-06 15:44:51,984 - kedro.io.data_catalog - INFO - Loading data from 'y_test' (MemoryDataSet)...
2022-09-06 15:44:51,986 - kedro.io.data_catalog - INFO - Loading data from 'X_test' (MemoryDataSet)...
2022-09-06 15:44:51,988 - kedro.io.data_catalog - INFO - Loading data from 'y_train' (MemoryDataSet)...
2022-09-06 15:44:51,989 - kedro.io.data_catalog - INFO - Loading data from 'X_train' (MemoryDataSet)...
2022-09-06 15:45:02,158 - kedro.framework.session.session - INFO - Kedro project kedro-experiment
2022-09-06 15:45:14,720 - kedro.framework.session.session - INFO - Kedro project kedro-experiment
2022-09-06 15:45:15,004 - py.warnings - WARNING - /home/linuxbrew/.linuxbrew/opt/python@3.10/lib/python3.10/site-packages/kedro/framework/context/context.py:344: UserWarning: Credentials not found in your Kedro project config.
No files found in ['/home/anarpego/cloud_team_devops/Experiments/Cloud_Build_Kedro/kedro-experiment/conf/base', '/home/anarpego/cloud_team_devops/Experiments/Cloud_Build_Kedro/kedro-experiment/conf/local'] matching the glob pattern(s): ['credentials*', 'credentials*/**', '**/credentials*']
  warn(f"Credentials not found in your Kedro project config.\n{str(exc)}")

2022-09-06 16:04:25,897 - kedro.framework.session.session - INFO - Kedro project kedro-experiment
2022-09-06 16:04:26,813 - py.warnings - WARNING - /home/linuxbrew/.linuxbrew/opt/python@3.10/lib/python3.10/site-packages/kedro/framework/context/context.py:344: UserWarning: Credentials not found in your Kedro project config.
No files found in ['/home/anarpego/cloud_team_devops/Experiments/Cloud_Build_Kedro/kedro-experiment/conf/base', '/home/anarpego/cloud_team_devops/Experiments/Cloud_Build_Kedro/kedro-experiment/conf/local'] matching the glob pattern(s): ['credentials*', 'credentials*/**', '**/credentials*']
  warn(f"Credentials not found in your Kedro project config.\n{str(exc)}")

2022-09-06 16:11:54,454 - kedro.framework.session.session - INFO - Kedro project kedro-experiment
2022-09-06 16:11:55,292 - py.warnings - WARNING - /home/linuxbrew/.linuxbrew/opt/python@3.10/lib/python3.10/site-packages/kedro/framework/context/context.py:344: UserWarning: Credentials not found in your Kedro project config.
No files found in ['/home/anarpego/cloud_team_devops/Experiments/Cloud_Build_Kedro/kedro-experiment/conf/base', '/home/anarpego/cloud_team_devops/Experiments/Cloud_Build_Kedro/kedro-experiment/conf/local'] matching the glob pattern(s): ['credentials*', 'credentials*/**', '**/credentials*']
  warn(f"Credentials not found in your Kedro project config.\n{str(exc)}")

2022-09-06 16:51:11,310 - py.warnings - WARNING - /home/linuxbrew/.linuxbrew/opt/python@3.10/lib/python3.10/site-packages/kfp/v2/google/client/client.py:169: FutureWarning: AIPlatformClient will be deprecated in v2.0.0. Please use PipelineJob https://googleapis.dev/python/aiplatform/latest/_modules/google/cloud/aiplatform/pipeline_jobs.html in Vertex SDK. Install the SDK using "pip install google-cloud-aiplatform"
  warnings.warn(

2022-09-06 16:51:11,317 - py.warnings - WARNING - /home/linuxbrew/.linuxbrew/opt/python@3.10/lib/python3.10/site-packages/google/auth/_default.py:70: UserWarning: Your application has authenticated using end user credentials from Google Cloud SDK without a quota project. You might receive a "quota exceeded" or "API not enabled" error. We recommend you rerun `gcloud auth application-default login` and make sure a quota project is added. Or you can use service accounts instead. For more information about service accounts, see https://cloud.google.com/docs/authentication/
  warnings.warn(_CLOUD_SDK_CREDENTIALS_WARNING)

2022-09-06 16:51:12,360 - py.warnings - WARNING - /home/linuxbrew/.linuxbrew/opt/python@3.10/lib/python3.10/site-packages/google/auth/_default.py:70: UserWarning: Your application has authenticated using end user credentials from Google Cloud SDK without a quota project. You might receive a "quota exceeded" or "API not enabled" error. We recommend you rerun `gcloud auth application-default login` and make sure a quota project is added. Or you can use service accounts instead. For more information about service accounts, see https://cloud.google.com/docs/authentication/
  warnings.warn(_CLOUD_SDK_CREDENTIALS_WARNING)

2022-09-06 16:51:12,789 - py.warnings - WARNING - /home/linuxbrew/.linuxbrew/opt/python@3.10/lib/python3.10/site-packages/kfp/v2/compiler/compiler.py:1292: FutureWarning: APIs imported from the v1 namespace (e.g. kfp.dsl, kfp.components, etc) will not be supported by the v2 compiler since v2.0.0
  warnings.warn(

2022-09-06 16:51:41,201 - py.warnings - WARNING - /home/linuxbrew/.linuxbrew/opt/python@3.10/lib/python3.10/site-packages/kfp/v2/google/client/client.py:169: FutureWarning: AIPlatformClient will be deprecated in v2.0.0. Please use PipelineJob https://googleapis.dev/python/aiplatform/latest/_modules/google/cloud/aiplatform/pipeline_jobs.html in Vertex SDK. Install the SDK using "pip install google-cloud-aiplatform"
  warnings.warn(

2022-09-06 16:51:41,205 - py.warnings - WARNING - /home/linuxbrew/.linuxbrew/opt/python@3.10/lib/python3.10/site-packages/google/auth/_default.py:70: UserWarning: Your application has authenticated using end user credentials from Google Cloud SDK without a quota project. You might receive a "quota exceeded" or "API not enabled" error. We recommend you rerun `gcloud auth application-default login` and make sure a quota project is added. Or you can use service accounts instead. For more information about service accounts, see https://cloud.google.com/docs/authentication/
  warnings.warn(_CLOUD_SDK_CREDENTIALS_WARNING)

2022-09-06 16:51:41,765 - py.warnings - WARNING - /home/linuxbrew/.linuxbrew/opt/python@3.10/lib/python3.10/site-packages/google/auth/_default.py:70: UserWarning: Your application has authenticated using end user credentials from Google Cloud SDK without a quota project. You might receive a "quota exceeded" or "API not enabled" error. We recommend you rerun `gcloud auth application-default login` and make sure a quota project is added. Or you can use service accounts instead. For more information about service accounts, see https://cloud.google.com/docs/authentication/
  warnings.warn(_CLOUD_SDK_CREDENTIALS_WARNING)

2022-09-06 16:51:42,216 - py.warnings - WARNING - /home/linuxbrew/.linuxbrew/opt/python@3.10/lib/python3.10/site-packages/kfp/v2/compiler/compiler.py:1292: FutureWarning: APIs imported from the v1 namespace (e.g. kfp.dsl, kfp.components, etc) will not be supported by the v2 compiler since v2.0.0
  warnings.warn(

2022-09-06 17:05:12,190 - kedro.framework.session.session - INFO - Kedro project kedro-experiment
2022-09-06 17:05:12,599 - kedro.io.data_catalog - INFO - Loading data from 'X_train' (CSVDataSet)...
2022-09-06 17:05:12,601 - kedro.runner.sequential_runner - WARNING - There are 1 nodes that have not run.
You can resume the pipeline run by adding the following argument to your previous command:

2022-09-06 17:09:01,865 - kedro.framework.session.session - INFO - Kedro project kedro-experiment
2022-09-06 17:09:02,171 - kedro.io.data_catalog - INFO - Loading data from 'X_train' (CSVDataSet)...
2022-09-06 17:09:02,173 - kedro.runner.sequential_runner - WARNING - There are 1 nodes that have not run.
You can resume the pipeline run by adding the following argument to your previous command:

2022-09-06 17:09:33,633 - kedro.framework.session.session - INFO - Kedro project kedro-experiment
2022-09-06 17:09:33,836 - kedro.io.data_catalog - INFO - Loading data from 'example_iris_data' (CSVDataSet)...
2022-09-06 17:09:33,845 - kedro.io.data_catalog - INFO - Loading data from 'parameters' (MemoryDataSet)...
2022-09-06 17:09:33,847 - kedro.pipeline.node - INFO - Running node: split: split_data([example_iris_data,parameters]) -> [X_train,X_test,y_train,y_test]
2022-09-06 17:09:33,854 - kedro.io.data_catalog - INFO - Saving data to 'X_train' (CSVDataSet)...
2022-09-06 17:09:33,859 - kedro.io.data_catalog - INFO - Saving data to 'X_test' (CSVDataSet)...
2022-09-06 17:09:33,861 - kedro.io.data_catalog - INFO - Saving data to 'y_train' (CSVDataSet)...
2022-09-06 17:09:33,864 - kedro.io.data_catalog - INFO - Saving data to 'y_test' (CSVDataSet)...
2022-09-06 17:09:33,866 - kedro.runner.sequential_runner - INFO - Completed 1 out of 1 tasks
2022-09-06 17:09:33,867 - kedro.runner.sequential_runner - INFO - Pipeline execution completed successfully.
2022-09-06 17:09:47,988 - kedro.framework.session.session - INFO - Kedro project kedro-experiment
2022-09-06 17:09:48,184 - kedro.io.data_catalog - INFO - Loading data from 'X_train' (CSVDataSet)...
2022-09-06 17:09:48,186 - kedro.io.data_catalog - INFO - Loading data from 'X_test' (CSVDataSet)...
2022-09-06 17:09:48,188 - kedro.io.data_catalog - INFO - Loading data from 'y_train' (CSVDataSet)...
2022-09-06 17:09:48,190 - kedro.pipeline.node - INFO - Running node: make_predictions: make_predictions([X_train,X_test,y_train]) -> [y_pred]
2022-09-06 17:09:48,192 - kedro.io.data_catalog - INFO - Saving data to 'y_pred' (CSVDataSet)...
2022-09-06 17:09:48,194 - kedro.runner.sequential_runner - INFO - Completed 1 out of 1 tasks
2022-09-06 17:09:48,195 - kedro.runner.sequential_runner - INFO - Pipeline execution completed successfully.
2022-09-06 17:12:28,979 - kedro.framework.session.session - INFO - Kedro project kedro-experiment
2022-09-06 17:12:29,246 - kedro.io.data_catalog - INFO - Loading data from 'y_pred' (CSVDataSet)...
2022-09-06 17:12:29,251 - kedro.io.data_catalog - INFO - Loading data from 'y_test' (CSVDataSet)...
2022-09-06 17:12:29,255 - kedro.pipeline.node - INFO - Running node: report_accuracy: report_accuracy([y_pred,y_test]) -> None
2022-09-06 17:12:29,264 - kedro_experiment.nodes - INFO - Model has accuracy of 0.933 on test data.
2022-09-06 17:12:29,266 - kedro.runner.sequential_runner - INFO - Completed 1 out of 1 tasks
2022-09-06 17:12:29,267 - kedro.runner.sequential_runner - INFO - Pipeline execution completed successfully.
2022-09-06 18:13:52,566 - py.warnings - WARNING - /home/linuxbrew/.linuxbrew/opt/python@3.10/lib/python3.10/site-packages/google/auth/_default.py:70: UserWarning: Your application has authenticated using end user credentials from Google Cloud SDK without a quota project. You might receive a "quota exceeded" or "API not enabled" error. We recommend you rerun `gcloud auth application-default login` and make sure a quota project is added. Or you can use service accounts instead. For more information about service accounts, see https://cloud.google.com/docs/authentication/
  warnings.warn(_CLOUD_SDK_CREDENTIALS_WARNING)

2022-09-06 18:15:54,722 - root - ERROR - Failed to get healthz info attempt 1 of 5.
Traceback (most recent call last):
  File "/home/linuxbrew/.linuxbrew/opt/python@3.10/lib/python3.10/site-packages/kfp/_client.py", line 411, in get_kfp_healthz
    response = self._healthz_api.get_healthz()
  File "/home/linuxbrew/.linuxbrew/opt/python@3.10/lib/python3.10/site-packages/kfp_server_api/api/healthz_service_api.py", line 63, in get_healthz
    return self.get_healthz_with_http_info(**kwargs)  # noqa: E501
  File "/home/linuxbrew/.linuxbrew/opt/python@3.10/lib/python3.10/site-packages/kfp_server_api/api/healthz_service_api.py", line 134, in get_healthz_with_http_info
    return self.api_client.call_api(
  File "/home/linuxbrew/.linuxbrew/opt/python@3.10/lib/python3.10/site-packages/kfp_server_api/api_client.py", line 364, in call_api
    return self.__call_api(resource_path, method,
  File "/home/linuxbrew/.linuxbrew/opt/python@3.10/lib/python3.10/site-packages/kfp_server_api/api_client.py", line 188, in __call_api
    raise e
  File "/home/linuxbrew/.linuxbrew/opt/python@3.10/lib/python3.10/site-packages/kfp_server_api/api_client.py", line 181, in __call_api
    response_data = self.request(
  File "/home/linuxbrew/.linuxbrew/opt/python@3.10/lib/python3.10/site-packages/kfp_server_api/api_client.py", line 389, in request
    return self.rest_client.GET(url,
  File "/home/linuxbrew/.linuxbrew/opt/python@3.10/lib/python3.10/site-packages/kfp_server_api/rest.py", line 230, in GET
    return self.request("GET", url,
  File "/home/linuxbrew/.linuxbrew/opt/python@3.10/lib/python3.10/site-packages/kfp_server_api/rest.py", line 224, in request
    raise ApiException(http_resp=r)
kfp_server_api.exceptions.ApiException: (524)
Reason: status code 524
HTTP response headers: HTTPHeaderDict({'Content-Length': '1440', 'Content-Type': 'text/html; charset=utf-8', 'Vary': 'Origin', 'X-Content-Type-Options': 'nosniff', 'X-Frame-Options': 'SAMEORIGIN', 'X-Xss-Protection': '0', 'Date': 'Wed, 07 Sep 2022 00:15:54 GMT', 'Set-Cookie': 'S=cloud_datalab_tunnel=ZdjmRvi0mAWumtt_CHlEimOa8XCD4NVilOd8YCrWxBo; Path=/; Max-Age=3600', 'Alt-Svc': 'h3=":443"; ma=2592000,h3-29=":443"; ma=2592000,h3-Q050=":443"; ma=2592000,h3-Q046=":443"; ma=2592000,h3-Q043=":443"; ma=2592000,quic=":443"; ma=2592000; v="46,43"'})
HTTP response body: 
<!DOCTYPE html>
<html lang=en>
  <meta charset=utf-8>
  <meta name=viewport content="initial-scale=1, minimum-scale=1, width=device-width">
  <title>Error 524 ()!!1</title>
  <style>
    *{margin:0;padding:0}html,code{font:15px/22px arial,sans-serif}html{background:#fff;color:#222;padding:15px}body{margin:7% auto 0;max-width:390px;min-height:180px;padding:30px 0 15px}* > body{background:url(//www.google.com/images/errors/robot.png) 100% 5px no-repeat;padding-right:205px}p{margin:11px 0 22px;overflow:hidden}ins{color:#777;text-decoration:none}a img{border:0}@media screen and (max-width:772px){body{background:none;margin-top:0;max-width:none;padding-right:0}}#logo{background:url(//www.google.com/images/logos/errorpage/error_logo-150x54.png) no-repeat;margin-left:-5px}@media only screen and (min-resolution:192dpi){#logo{background:url(//www.google.com/images/logos/errorpage/error_logo-150x54-2x.png) no-repeat 0% 0%/100% 100%;-moz-border-image:url(//www.google.com/images/logos/errorpage/error_logo-150x54-2x.png) 0}}@media only screen and (-webkit-min-device-pixel-ratio:2){#logo{background:url(//www.google.com/images/logos/errorpage/error_logo-150x54-2x.png) no-repeat;-webkit-background-size:100% 100%}}#logo{display:inline-block;height:54px;width:150px}
  </style>
  <a href=//www.google.com/><span id=logo aria-label=Google></span></a>
  <p><b>524.</b> <ins>That’s an error.</ins>
  <p>  <ins>That’s all we know.</ins>


2022-09-06 18:18:00,299 - root - ERROR - Failed to get healthz info attempt 2 of 5.
Traceback (most recent call last):
  File "/home/linuxbrew/.linuxbrew/opt/python@3.10/lib/python3.10/site-packages/kfp/_client.py", line 411, in get_kfp_healthz
    response = self._healthz_api.get_healthz()
  File "/home/linuxbrew/.linuxbrew/opt/python@3.10/lib/python3.10/site-packages/kfp_server_api/api/healthz_service_api.py", line 63, in get_healthz
    return self.get_healthz_with_http_info(**kwargs)  # noqa: E501
  File "/home/linuxbrew/.linuxbrew/opt/python@3.10/lib/python3.10/site-packages/kfp_server_api/api/healthz_service_api.py", line 134, in get_healthz_with_http_info
    return self.api_client.call_api(
  File "/home/linuxbrew/.linuxbrew/opt/python@3.10/lib/python3.10/site-packages/kfp_server_api/api_client.py", line 364, in call_api
    return self.__call_api(resource_path, method,
  File "/home/linuxbrew/.linuxbrew/opt/python@3.10/lib/python3.10/site-packages/kfp_server_api/api_client.py", line 188, in __call_api
    raise e
  File "/home/linuxbrew/.linuxbrew/opt/python@3.10/lib/python3.10/site-packages/kfp_server_api/api_client.py", line 181, in __call_api
    response_data = self.request(
  File "/home/linuxbrew/.linuxbrew/opt/python@3.10/lib/python3.10/site-packages/kfp_server_api/api_client.py", line 389, in request
    return self.rest_client.GET(url,
  File "/home/linuxbrew/.linuxbrew/opt/python@3.10/lib/python3.10/site-packages/kfp_server_api/rest.py", line 230, in GET
    return self.request("GET", url,
  File "/home/linuxbrew/.linuxbrew/opt/python@3.10/lib/python3.10/site-packages/kfp_server_api/rest.py", line 224, in request
    raise ApiException(http_resp=r)
kfp_server_api.exceptions.ApiException: (524)
Reason: status code 524
HTTP response headers: HTTPHeaderDict({'Content-Length': '1440', 'Content-Type': 'text/html; charset=utf-8', 'Date': 'Wed, 07 Sep 2022 00:18:00 GMT', 'Vary': 'Origin', 'X-Content-Type-Options': 'nosniff', 'X-Frame-Options': 'SAMEORIGIN', 'X-Xss-Protection': '0', 'Set-Cookie': 'S=cloud_datalab_tunnel=ZdjmRvi0mAWumtt_CHlEimOa8XCD4NVilOd8YCrWxBo; Path=/; Max-Age=3600', 'Alt-Svc': 'h3=":443"; ma=2592000,h3-29=":443"; ma=2592000,h3-Q050=":443"; ma=2592000,h3-Q046=":443"; ma=2592000,h3-Q043=":443"; ma=2592000,quic=":443"; ma=2592000; v="46,43"'})
HTTP response body: 
<!DOCTYPE html>
<html lang=en>
  <meta charset=utf-8>
  <meta name=viewport content="initial-scale=1, minimum-scale=1, width=device-width">
  <title>Error 524 ()!!1</title>
  <style>
    *{margin:0;padding:0}html,code{font:15px/22px arial,sans-serif}html{background:#fff;color:#222;padding:15px}body{margin:7% auto 0;max-width:390px;min-height:180px;padding:30px 0 15px}* > body{background:url(//www.google.com/images/errors/robot.png) 100% 5px no-repeat;padding-right:205px}p{margin:11px 0 22px;overflow:hidden}ins{color:#777;text-decoration:none}a img{border:0}@media screen and (max-width:772px){body{background:none;margin-top:0;max-width:none;padding-right:0}}#logo{background:url(//www.google.com/images/logos/errorpage/error_logo-150x54.png) no-repeat;margin-left:-5px}@media only screen and (min-resolution:192dpi){#logo{background:url(//www.google.com/images/logos/errorpage/error_logo-150x54-2x.png) no-repeat 0% 0%/100% 100%;-moz-border-image:url(//www.google.com/images/logos/errorpage/error_logo-150x54-2x.png) 0}}@media only screen and (-webkit-min-device-pixel-ratio:2){#logo{background:url(//www.google.com/images/logos/errorpage/error_logo-150x54-2x.png) no-repeat;-webkit-background-size:100% 100%}}#logo{display:inline-block;height:54px;width:150px}
  </style>
  <a href=//www.google.com/><span id=logo aria-label=Google></span></a>
  <p><b>524.</b> <ins>That’s an error.</ins>
  <p>  <ins>That’s all we know.</ins>


2022-09-06 18:20:05,732 - root - ERROR - Failed to get healthz info attempt 3 of 5.
Traceback (most recent call last):
  File "/home/linuxbrew/.linuxbrew/opt/python@3.10/lib/python3.10/site-packages/kfp/_client.py", line 411, in get_kfp_healthz
    response = self._healthz_api.get_healthz()
  File "/home/linuxbrew/.linuxbrew/opt/python@3.10/lib/python3.10/site-packages/kfp_server_api/api/healthz_service_api.py", line 63, in get_healthz
    return self.get_healthz_with_http_info(**kwargs)  # noqa: E501
  File "/home/linuxbrew/.linuxbrew/opt/python@3.10/lib/python3.10/site-packages/kfp_server_api/api/healthz_service_api.py", line 134, in get_healthz_with_http_info
    return self.api_client.call_api(
  File "/home/linuxbrew/.linuxbrew/opt/python@3.10/lib/python3.10/site-packages/kfp_server_api/api_client.py", line 364, in call_api
    return self.__call_api(resource_path, method,
  File "/home/linuxbrew/.linuxbrew/opt/python@3.10/lib/python3.10/site-packages/kfp_server_api/api_client.py", line 188, in __call_api
    raise e
  File "/home/linuxbrew/.linuxbrew/opt/python@3.10/lib/python3.10/site-packages/kfp_server_api/api_client.py", line 181, in __call_api
    response_data = self.request(
  File "/home/linuxbrew/.linuxbrew/opt/python@3.10/lib/python3.10/site-packages/kfp_server_api/api_client.py", line 389, in request
    return self.rest_client.GET(url,
  File "/home/linuxbrew/.linuxbrew/opt/python@3.10/lib/python3.10/site-packages/kfp_server_api/rest.py", line 230, in GET
    return self.request("GET", url,
  File "/home/linuxbrew/.linuxbrew/opt/python@3.10/lib/python3.10/site-packages/kfp_server_api/rest.py", line 224, in request
    raise ApiException(http_resp=r)
kfp_server_api.exceptions.ApiException: (524)
Reason: status code 524
HTTP response headers: HTTPHeaderDict({'Content-Length': '1440', 'Content-Type': 'text/html; charset=utf-8', 'Date': 'Wed, 07 Sep 2022 00:20:05 GMT', 'Vary': 'Origin', 'X-Content-Type-Options': 'nosniff', 'X-Frame-Options': 'SAMEORIGIN', 'X-Xss-Protection': '0', 'Set-Cookie': 'S=cloud_datalab_tunnel=ZdjmRvi0mAWumtt_CHlEimOa8XCD4NVilOd8YCrWxBo; Path=/; Max-Age=3600', 'Alt-Svc': 'h3=":443"; ma=2592000,h3-29=":443"; ma=2592000,h3-Q050=":443"; ma=2592000,h3-Q046=":443"; ma=2592000,h3-Q043=":443"; ma=2592000,quic=":443"; ma=2592000; v="46,43"'})
HTTP response body: 
<!DOCTYPE html>
<html lang=en>
  <meta charset=utf-8>
  <meta name=viewport content="initial-scale=1, minimum-scale=1, width=device-width">
  <title>Error 524 ()!!1</title>
  <style>
    *{margin:0;padding:0}html,code{font:15px/22px arial,sans-serif}html{background:#fff;color:#222;padding:15px}body{margin:7% auto 0;max-width:390px;min-height:180px;padding:30px 0 15px}* > body{background:url(//www.google.com/images/errors/robot.png) 100% 5px no-repeat;padding-right:205px}p{margin:11px 0 22px;overflow:hidden}ins{color:#777;text-decoration:none}a img{border:0}@media screen and (max-width:772px){body{background:none;margin-top:0;max-width:none;padding-right:0}}#logo{background:url(//www.google.com/images/logos/errorpage/error_logo-150x54.png) no-repeat;margin-left:-5px}@media only screen and (min-resolution:192dpi){#logo{background:url(//www.google.com/images/logos/errorpage/error_logo-150x54-2x.png) no-repeat 0% 0%/100% 100%;-moz-border-image:url(//www.google.com/images/logos/errorpage/error_logo-150x54-2x.png) 0}}@media only screen and (-webkit-min-device-pixel-ratio:2){#logo{background:url(//www.google.com/images/logos/errorpage/error_logo-150x54-2x.png) no-repeat;-webkit-background-size:100% 100%}}#logo{display:inline-block;height:54px;width:150px}
  </style>
  <a href=//www.google.com/><span id=logo aria-label=Google></span></a>
  <p><b>524.</b> <ins>That’s an error.</ins>
  <p>  <ins>That’s all we know.</ins>


2022-09-06 18:22:11,247 - root - ERROR - Failed to get healthz info attempt 4 of 5.
Traceback (most recent call last):
  File "/home/linuxbrew/.linuxbrew/opt/python@3.10/lib/python3.10/site-packages/kfp/_client.py", line 411, in get_kfp_healthz
    response = self._healthz_api.get_healthz()
  File "/home/linuxbrew/.linuxbrew/opt/python@3.10/lib/python3.10/site-packages/kfp_server_api/api/healthz_service_api.py", line 63, in get_healthz
    return self.get_healthz_with_http_info(**kwargs)  # noqa: E501
  File "/home/linuxbrew/.linuxbrew/opt/python@3.10/lib/python3.10/site-packages/kfp_server_api/api/healthz_service_api.py", line 134, in get_healthz_with_http_info
    return self.api_client.call_api(
  File "/home/linuxbrew/.linuxbrew/opt/python@3.10/lib/python3.10/site-packages/kfp_server_api/api_client.py", line 364, in call_api
    return self.__call_api(resource_path, method,
  File "/home/linuxbrew/.linuxbrew/opt/python@3.10/lib/python3.10/site-packages/kfp_server_api/api_client.py", line 188, in __call_api
    raise e
  File "/home/linuxbrew/.linuxbrew/opt/python@3.10/lib/python3.10/site-packages/kfp_server_api/api_client.py", line 181, in __call_api
    response_data = self.request(
  File "/home/linuxbrew/.linuxbrew/opt/python@3.10/lib/python3.10/site-packages/kfp_server_api/api_client.py", line 389, in request
    return self.rest_client.GET(url,
  File "/home/linuxbrew/.linuxbrew/opt/python@3.10/lib/python3.10/site-packages/kfp_server_api/rest.py", line 230, in GET
    return self.request("GET", url,
  File "/home/linuxbrew/.linuxbrew/opt/python@3.10/lib/python3.10/site-packages/kfp_server_api/rest.py", line 224, in request
    raise ApiException(http_resp=r)
kfp_server_api.exceptions.ApiException: (524)
Reason: status code 524
HTTP response headers: HTTPHeaderDict({'Content-Length': '1440', 'Content-Type': 'text/html; charset=utf-8', 'Date': 'Wed, 07 Sep 2022 00:22:11 GMT', 'Vary': 'Origin', 'X-Content-Type-Options': 'nosniff', 'X-Frame-Options': 'SAMEORIGIN', 'X-Xss-Protection': '0', 'Set-Cookie': 'S=cloud_datalab_tunnel=ZdjmRvi0mAWumtt_CHlEimOa8XCD4NVilOd8YCrWxBo; Path=/; Max-Age=3600', 'Alt-Svc': 'h3=":443"; ma=2592000,h3-29=":443"; ma=2592000,h3-Q050=":443"; ma=2592000,h3-Q046=":443"; ma=2592000,h3-Q043=":443"; ma=2592000,quic=":443"; ma=2592000; v="46,43"'})
HTTP response body: 
<!DOCTYPE html>
<html lang=en>
  <meta charset=utf-8>
  <meta name=viewport content="initial-scale=1, minimum-scale=1, width=device-width">
  <title>Error 524 ()!!1</title>
  <style>
    *{margin:0;padding:0}html,code{font:15px/22px arial,sans-serif}html{background:#fff;color:#222;padding:15px}body{margin:7% auto 0;max-width:390px;min-height:180px;padding:30px 0 15px}* > body{background:url(//www.google.com/images/errors/robot.png) 100% 5px no-repeat;padding-right:205px}p{margin:11px 0 22px;overflow:hidden}ins{color:#777;text-decoration:none}a img{border:0}@media screen and (max-width:772px){body{background:none;margin-top:0;max-width:none;padding-right:0}}#logo{background:url(//www.google.com/images/logos/errorpage/error_logo-150x54.png) no-repeat;margin-left:-5px}@media only screen and (min-resolution:192dpi){#logo{background:url(//www.google.com/images/logos/errorpage/error_logo-150x54-2x.png) no-repeat 0% 0%/100% 100%;-moz-border-image:url(//www.google.com/images/logos/errorpage/error_logo-150x54-2x.png) 0}}@media only screen and (-webkit-min-device-pixel-ratio:2){#logo{background:url(//www.google.com/images/logos/errorpage/error_logo-150x54-2x.png) no-repeat;-webkit-background-size:100% 100%}}#logo{display:inline-block;height:54px;width:150px}
  </style>
  <a href=//www.google.com/><span id=logo aria-label=Google></span></a>
  <p><b>524.</b> <ins>That’s an error.</ins>
  <p>  <ins>That’s all we know.</ins>


2022-09-06 18:24:16,623 - root - ERROR - Failed to get healthz info attempt 5 of 5.
Traceback (most recent call last):
  File "/home/linuxbrew/.linuxbrew/opt/python@3.10/lib/python3.10/site-packages/kfp/_client.py", line 411, in get_kfp_healthz
    response = self._healthz_api.get_healthz()
  File "/home/linuxbrew/.linuxbrew/opt/python@3.10/lib/python3.10/site-packages/kfp_server_api/api/healthz_service_api.py", line 63, in get_healthz
    return self.get_healthz_with_http_info(**kwargs)  # noqa: E501
  File "/home/linuxbrew/.linuxbrew/opt/python@3.10/lib/python3.10/site-packages/kfp_server_api/api/healthz_service_api.py", line 134, in get_healthz_with_http_info
    return self.api_client.call_api(
  File "/home/linuxbrew/.linuxbrew/opt/python@3.10/lib/python3.10/site-packages/kfp_server_api/api_client.py", line 364, in call_api
    return self.__call_api(resource_path, method,
  File "/home/linuxbrew/.linuxbrew/opt/python@3.10/lib/python3.10/site-packages/kfp_server_api/api_client.py", line 188, in __call_api
    raise e
  File "/home/linuxbrew/.linuxbrew/opt/python@3.10/lib/python3.10/site-packages/kfp_server_api/api_client.py", line 181, in __call_api
    response_data = self.request(
  File "/home/linuxbrew/.linuxbrew/opt/python@3.10/lib/python3.10/site-packages/kfp_server_api/api_client.py", line 389, in request
    return self.rest_client.GET(url,
  File "/home/linuxbrew/.linuxbrew/opt/python@3.10/lib/python3.10/site-packages/kfp_server_api/rest.py", line 230, in GET
    return self.request("GET", url,
  File "/home/linuxbrew/.linuxbrew/opt/python@3.10/lib/python3.10/site-packages/kfp_server_api/rest.py", line 224, in request
    raise ApiException(http_resp=r)
kfp_server_api.exceptions.ApiException: (524)
Reason: status code 524
HTTP response headers: HTTPHeaderDict({'Content-Length': '1440', 'Content-Type': 'text/html; charset=utf-8', 'Date': 'Wed, 07 Sep 2022 00:24:16 GMT', 'Vary': 'Origin', 'X-Content-Type-Options': 'nosniff', 'X-Frame-Options': 'SAMEORIGIN', 'X-Xss-Protection': '0', 'Set-Cookie': 'S=cloud_datalab_tunnel=ZdjmRvi0mAWumtt_CHlEimOa8XCD4NVilOd8YCrWxBo; Path=/; Max-Age=3600', 'Alt-Svc': 'h3=":443"; ma=2592000,h3-29=":443"; ma=2592000,h3-Q050=":443"; ma=2592000,h3-Q046=":443"; ma=2592000,h3-Q043=":443"; ma=2592000,quic=":443"; ma=2592000; v="46,43"'})
HTTP response body: 
<!DOCTYPE html>
<html lang=en>
  <meta charset=utf-8>
  <meta name=viewport content="initial-scale=1, minimum-scale=1, width=device-width">
  <title>Error 524 ()!!1</title>
  <style>
    *{margin:0;padding:0}html,code{font:15px/22px arial,sans-serif}html{background:#fff;color:#222;padding:15px}body{margin:7% auto 0;max-width:390px;min-height:180px;padding:30px 0 15px}* > body{background:url(//www.google.com/images/errors/robot.png) 100% 5px no-repeat;padding-right:205px}p{margin:11px 0 22px;overflow:hidden}ins{color:#777;text-decoration:none}a img{border:0}@media screen and (max-width:772px){body{background:none;margin-top:0;max-width:none;padding-right:0}}#logo{background:url(//www.google.com/images/logos/errorpage/error_logo-150x54.png) no-repeat;margin-left:-5px}@media only screen and (min-resolution:192dpi){#logo{background:url(//www.google.com/images/logos/errorpage/error_logo-150x54-2x.png) no-repeat 0% 0%/100% 100%;-moz-border-image:url(//www.google.com/images/logos/errorpage/error_logo-150x54-2x.png) 0}}@media only screen and (-webkit-min-device-pixel-ratio:2){#logo{background:url(//www.google.com/images/logos/errorpage/error_logo-150x54-2x.png) no-repeat;-webkit-background-size:100% 100%}}#logo{display:inline-block;height:54px;width:150px}
  </style>
  <a href=//www.google.com/><span id=logo aria-label=Google></span></a>
  <p><b>524.</b> <ins>That’s an error.</ins>
  <p>  <ins>That’s all we know.</ins>


2022-09-07 08:40:47,648 - kedro.framework.session.session - INFO - Kedro project kedro-experiment
2022-09-07 08:40:48,161 - kedro.io.data_catalog - INFO - Loading data from 'example_iris_data' (CSVDataSet)...
2022-09-07 08:40:48,166 - kedro.io.data_catalog - INFO - Loading data from 'parameters' (MemoryDataSet)...
2022-09-07 08:40:48,167 - kedro.pipeline.node - INFO - Running node: split: split_data([example_iris_data,parameters]) -> [X_train,X_test,y_train,y_test]
2022-09-07 08:40:48,172 - kedro.io.data_catalog - INFO - Saving data to 'X_train' (CSVDataSet)...
2022-09-07 08:40:48,175 - kedro.io.data_catalog - INFO - Saving data to 'X_test' (CSVDataSet)...
2022-09-07 08:40:48,177 - kedro.io.data_catalog - INFO - Saving data to 'y_train' (CSVDataSet)...
2022-09-07 08:40:48,179 - kedro.io.data_catalog - INFO - Saving data to 'y_test' (CSVDataSet)...
2022-09-07 08:40:48,181 - kedro.runner.sequential_runner - INFO - Completed 1 out of 1 tasks
2022-09-07 08:40:48,182 - kedro.runner.sequential_runner - INFO - Pipeline execution completed successfully.
2022-09-07 08:41:16,631 - kedro.framework.session.session - INFO - Kedro project kedro-experiment
2022-09-07 08:41:16,846 - kedro.io.data_catalog - INFO - Loading data from 'X_train' (CSVDataSet)...
2022-09-07 08:41:16,849 - kedro.io.data_catalog - INFO - Loading data from 'X_test' (CSVDataSet)...
2022-09-07 08:41:16,851 - kedro.io.data_catalog - INFO - Loading data from 'y_train' (CSVDataSet)...
2022-09-07 08:41:16,854 - kedro.pipeline.node - INFO - Running node: make_predictions: make_predictions([X_train,X_test,y_train]) -> [y_pred]
2022-09-07 08:41:16,857 - kedro.io.data_catalog - INFO - Saving data to 'y_pred' (CSVDataSet)...
2022-09-07 08:41:16,860 - kedro.runner.sequential_runner - INFO - Completed 1 out of 1 tasks
2022-09-07 08:41:16,861 - kedro.runner.sequential_runner - INFO - Pipeline execution completed successfully.
2022-09-07 08:41:26,393 - kedro.framework.session.session - INFO - Kedro project kedro-experiment
2022-09-07 08:41:26,596 - kedro.io.data_catalog - INFO - Loading data from 'y_pred' (CSVDataSet)...
2022-09-07 08:41:26,599 - kedro.io.data_catalog - INFO - Loading data from 'y_test' (CSVDataSet)...
2022-09-07 08:41:26,601 - kedro.pipeline.node - INFO - Running node: report_accuracy: report_accuracy([y_pred,y_test]) -> [z_output]
2022-09-07 08:41:26,603 - kedro_experiment.nodes - INFO - Model has accuracy of 0.933 on test data.
2022-09-07 08:41:26,604 - kedro.io.data_catalog - INFO - Saving data to 'z_output' (CSVDataSet)...
2022-09-07 08:41:26,606 - kedro.runner.sequential_runner - WARNING - There are 1 nodes that have not run.
You can resume the pipeline run by adding the following argument to your previous command:

2022-09-07 08:43:58,858 - kedro.framework.session.session - INFO - Kedro project kedro-experiment
2022-09-07 08:43:59,057 - kedro.io.data_catalog - INFO - Loading data from 'y_pred' (CSVDataSet)...
2022-09-07 08:43:59,061 - kedro.io.data_catalog - INFO - Loading data from 'y_test' (CSVDataSet)...
2022-09-07 08:43:59,064 - kedro.pipeline.node - INFO - Running node: report_accuracy: report_accuracy([y_pred,y_test]) -> [z_output]
2022-09-07 08:43:59,066 - kedro_experiment.nodes - INFO - Model has accuracy of 0.933 on test data.
2022-09-07 08:43:59,067 - kedro.pipeline.node - ERROR - Node 'report_accuracy: report_accuracy([y_pred,y_test]) -> [z_output]' failed with error: 
Failed to save outputs of node report_accuracy: report_accuracy([y_pred,y_test]) -> [z_output].
The node definition contains a list of outputs ['z_output'], whereas the node function returned a 'NoneType'.
2022-09-07 08:43:59,070 - kedro.runner.sequential_runner - WARNING - There are 1 nodes that have not run.
You can resume the pipeline run by adding the following argument to your previous command:

2022-09-07 08:45:47,538 - kedro.framework.session.session - INFO - Kedro project kedro-experiment
2022-09-07 08:45:47,764 - kedro.io.data_catalog - INFO - Loading data from 'example_iris_data' (CSVDataSet)...
2022-09-07 08:45:47,767 - kedro.io.data_catalog - INFO - Loading data from 'parameters' (MemoryDataSet)...
2022-09-07 08:45:47,769 - kedro.pipeline.node - INFO - Running node: split: split_data([example_iris_data,parameters]) -> [X_train,X_test,y_train,y_test]
2022-09-07 08:45:47,771 - kedro.io.data_catalog - INFO - Saving data to 'X_train' (CSVDataSet)...
2022-09-07 08:45:47,775 - kedro.io.data_catalog - INFO - Saving data to 'X_test' (CSVDataSet)...
2022-09-07 08:45:47,777 - kedro.io.data_catalog - INFO - Saving data to 'y_train' (CSVDataSet)...
2022-09-07 08:45:47,778 - kedro.io.data_catalog - INFO - Saving data to 'y_test' (CSVDataSet)...
2022-09-07 08:45:47,780 - kedro.runner.sequential_runner - INFO - Completed 1 out of 1 tasks
2022-09-07 08:45:47,781 - kedro.runner.sequential_runner - INFO - Pipeline execution completed successfully.
2022-09-07 08:45:51,722 - kedro.framework.session.session - INFO - Kedro project kedro-experiment
2022-09-07 08:45:51,920 - kedro.io.data_catalog - INFO - Loading data from 'X_train' (CSVDataSet)...
2022-09-07 08:45:51,923 - kedro.io.data_catalog - INFO - Loading data from 'X_test' (CSVDataSet)...
2022-09-07 08:45:51,925 - kedro.io.data_catalog - INFO - Loading data from 'y_train' (CSVDataSet)...
2022-09-07 08:45:51,927 - kedro.pipeline.node - INFO - Running node: make_predictions: make_predictions([X_train,X_test,y_train]) -> [y_pred]
2022-09-07 08:45:51,929 - kedro.io.data_catalog - INFO - Saving data to 'y_pred' (CSVDataSet)...
2022-09-07 08:45:51,931 - kedro.runner.sequential_runner - INFO - Completed 1 out of 1 tasks
2022-09-07 08:45:51,931 - kedro.runner.sequential_runner - INFO - Pipeline execution completed successfully.
2022-09-07 08:45:55,780 - kedro.framework.session.session - INFO - Kedro project kedro-experiment
2022-09-07 08:45:55,995 - kedro.io.data_catalog - INFO - Loading data from 'y_pred' (CSVDataSet)...
2022-09-07 08:45:55,998 - kedro.io.data_catalog - INFO - Loading data from 'y_test' (CSVDataSet)...
2022-09-07 08:45:56,000 - kedro.pipeline.node - INFO - Running node: report_accuracy: report_accuracy([y_pred,y_test]) -> [accuracy]
2022-09-07 08:45:56,002 - kedro_experiment.nodes - INFO - Model has accuracy of 0.933 on test data.
2022-09-07 08:45:56,003 - kedro.io.data_catalog - INFO - Saving data to 'accuracy' (MemoryDataSet)...
2022-09-07 08:45:56,004 - kedro.runner.sequential_runner - INFO - Completed 1 out of 1 tasks
2022-09-07 08:45:56,005 - kedro.runner.sequential_runner - INFO - Pipeline execution completed successfully.
2022-09-07 08:45:56,006 - kedro.io.data_catalog - INFO - Loading data from 'accuracy' (MemoryDataSet)...
2022-09-07 08:46:58,179 - kedro.framework.session.session - INFO - Kedro project kedro-experiment
2022-09-07 08:46:58,382 - kedro.io.data_catalog - INFO - Loading data from 'example_iris_data' (CSVDataSet)...
2022-09-07 08:46:58,385 - kedro.io.data_catalog - INFO - Loading data from 'parameters' (MemoryDataSet)...
2022-09-07 08:46:58,387 - kedro.pipeline.node - INFO - Running node: split: split_data([example_iris_data,parameters]) -> [X_train,X_test,y_train,y_test]
2022-09-07 08:46:58,389 - kedro.io.data_catalog - INFO - Saving data to 'X_train' (CSVDataSet)...
2022-09-07 08:46:58,391 - kedro.io.data_catalog - INFO - Saving data to 'X_test' (CSVDataSet)...
2022-09-07 08:46:58,393 - kedro.io.data_catalog - INFO - Saving data to 'y_train' (CSVDataSet)...
2022-09-07 08:46:58,395 - kedro.io.data_catalog - INFO - Saving data to 'y_test' (CSVDataSet)...
2022-09-07 08:46:58,398 - kedro.runner.sequential_runner - INFO - Completed 1 out of 1 tasks
2022-09-07 08:46:58,399 - kedro.runner.sequential_runner - INFO - Pipeline execution completed successfully.
2022-09-07 08:47:01,229 - kedro.framework.session.session - INFO - Kedro project kedro-experiment
2022-09-07 08:47:01,430 - kedro.io.data_catalog - INFO - Loading data from 'y_pred' (CSVDataSet)...
2022-09-07 08:47:01,434 - kedro.io.data_catalog - INFO - Loading data from 'y_test' (CSVDataSet)...
2022-09-07 08:47:01,436 - kedro.pipeline.node - INFO - Running node: report_accuracy: report_accuracy([y_pred,y_test]) -> [accuracy]
2022-09-07 08:47:01,438 - kedro_experiment.nodes - INFO - Model has accuracy of 0.933 on test data.
2022-09-07 08:47:01,439 - kedro.io.data_catalog - INFO - Saving data to 'accuracy' (CSVDataSet)...
2022-09-07 08:47:01,441 - kedro.runner.sequential_runner - INFO - Completed 1 out of 1 tasks
2022-09-07 08:47:01,442 - kedro.runner.sequential_runner - INFO - Pipeline execution completed successfully.
2022-09-07 08:47:04,574 - kedro.framework.session.session - INFO - Kedro project kedro-experiment
2022-09-07 08:47:04,778 - kedro.io.data_catalog - INFO - Loading data from 'y_pred' (CSVDataSet)...
2022-09-07 08:47:04,781 - kedro.io.data_catalog - INFO - Loading data from 'y_test' (CSVDataSet)...
2022-09-07 08:47:04,784 - kedro.pipeline.node - INFO - Running node: report_accuracy: report_accuracy([y_pred,y_test]) -> [accuracy]
2022-09-07 08:47:04,786 - kedro_experiment.nodes - INFO - Model has accuracy of 0.933 on test data.
2022-09-07 08:47:04,787 - kedro.io.data_catalog - INFO - Saving data to 'accuracy' (CSVDataSet)...
2022-09-07 08:47:04,789 - kedro.runner.sequential_runner - INFO - Completed 1 out of 1 tasks
2022-09-07 08:47:04,790 - kedro.runner.sequential_runner - INFO - Pipeline execution completed successfully.
2022-09-07 10:53:20,865 - py.warnings - WARNING - /home/linuxbrew/.linuxbrew/opt/python@3.10/lib/python3.10/site-packages/google/auth/_default.py:70: UserWarning: Your application has authenticated using end user credentials from Google Cloud SDK without a quota project. You might receive a "quota exceeded" or "API not enabled" error. We recommend you rerun `gcloud auth application-default login` and make sure a quota project is added. Or you can use service accounts instead. For more information about service accounts, see https://cloud.google.com/docs/authentication/
  warnings.warn(_CLOUD_SDK_CREDENTIALS_WARNING)

2022-09-07 10:55:23,183 - root - ERROR - Failed to get healthz info attempt 1 of 5.
Traceback (most recent call last):
  File "/home/linuxbrew/.linuxbrew/opt/python@3.10/lib/python3.10/site-packages/kfp/_client.py", line 411, in get_kfp_healthz
    response = self._healthz_api.get_healthz()
  File "/home/linuxbrew/.linuxbrew/opt/python@3.10/lib/python3.10/site-packages/kfp_server_api/api/healthz_service_api.py", line 63, in get_healthz
    return self.get_healthz_with_http_info(**kwargs)  # noqa: E501
  File "/home/linuxbrew/.linuxbrew/opt/python@3.10/lib/python3.10/site-packages/kfp_server_api/api/healthz_service_api.py", line 134, in get_healthz_with_http_info
    return self.api_client.call_api(
  File "/home/linuxbrew/.linuxbrew/opt/python@3.10/lib/python3.10/site-packages/kfp_server_api/api_client.py", line 364, in call_api
    return self.__call_api(resource_path, method,
  File "/home/linuxbrew/.linuxbrew/opt/python@3.10/lib/python3.10/site-packages/kfp_server_api/api_client.py", line 188, in __call_api
    raise e
  File "/home/linuxbrew/.linuxbrew/opt/python@3.10/lib/python3.10/site-packages/kfp_server_api/api_client.py", line 181, in __call_api
    response_data = self.request(
  File "/home/linuxbrew/.linuxbrew/opt/python@3.10/lib/python3.10/site-packages/kfp_server_api/api_client.py", line 389, in request
    return self.rest_client.GET(url,
  File "/home/linuxbrew/.linuxbrew/opt/python@3.10/lib/python3.10/site-packages/kfp_server_api/rest.py", line 230, in GET
    return self.request("GET", url,
  File "/home/linuxbrew/.linuxbrew/opt/python@3.10/lib/python3.10/site-packages/kfp_server_api/rest.py", line 224, in request
    raise ApiException(http_resp=r)
kfp_server_api.exceptions.ApiException: (524)
Reason: status code 524
HTTP response headers: HTTPHeaderDict({'Content-Length': '1440', 'Content-Type': 'text/html; charset=utf-8', 'Date': 'Wed, 07 Sep 2022 16:55:23 GMT', 'Vary': 'Origin', 'X-Content-Type-Options': 'nosniff', 'X-Frame-Options': 'SAMEORIGIN', 'X-Xss-Protection': '0', 'Set-Cookie': 'S=cloud_datalab_tunnel=AhUMZyywos2t016IR5Pokb5rfUEY6gmHqXuUa-BLTs4; Path=/; Max-Age=3600', 'Alt-Svc': 'h3=":443"; ma=2592000,h3-29=":443"; ma=2592000,h3-Q050=":443"; ma=2592000,h3-Q046=":443"; ma=2592000,h3-Q043=":443"; ma=2592000,quic=":443"; ma=2592000; v="46,43"'})
HTTP response body: 
<!DOCTYPE html>
<html lang=en>
  <meta charset=utf-8>
  <meta name=viewport content="initial-scale=1, minimum-scale=1, width=device-width">
  <title>Error 524 ()!!1</title>
  <style>
    *{margin:0;padding:0}html,code{font:15px/22px arial,sans-serif}html{background:#fff;color:#222;padding:15px}body{margin:7% auto 0;max-width:390px;min-height:180px;padding:30px 0 15px}* > body{background:url(//www.google.com/images/errors/robot.png) 100% 5px no-repeat;padding-right:205px}p{margin:11px 0 22px;overflow:hidden}ins{color:#777;text-decoration:none}a img{border:0}@media screen and (max-width:772px){body{background:none;margin-top:0;max-width:none;padding-right:0}}#logo{background:url(//www.google.com/images/logos/errorpage/error_logo-150x54.png) no-repeat;margin-left:-5px}@media only screen and (min-resolution:192dpi){#logo{background:url(//www.google.com/images/logos/errorpage/error_logo-150x54-2x.png) no-repeat 0% 0%/100% 100%;-moz-border-image:url(//www.google.com/images/logos/errorpage/error_logo-150x54-2x.png) 0}}@media only screen and (-webkit-min-device-pixel-ratio:2){#logo{background:url(//www.google.com/images/logos/errorpage/error_logo-150x54-2x.png) no-repeat;-webkit-background-size:100% 100%}}#logo{display:inline-block;height:54px;width:150px}
  </style>
  <a href=//www.google.com/><span id=logo aria-label=Google></span></a>
  <p><b>524.</b> <ins>That’s an error.</ins>
  <p>  <ins>That’s all we know.</ins>


2022-09-07 10:57:28,595 - root - ERROR - Failed to get healthz info attempt 2 of 5.
Traceback (most recent call last):
  File "/home/linuxbrew/.linuxbrew/opt/python@3.10/lib/python3.10/site-packages/kfp/_client.py", line 411, in get_kfp_healthz
    response = self._healthz_api.get_healthz()
  File "/home/linuxbrew/.linuxbrew/opt/python@3.10/lib/python3.10/site-packages/kfp_server_api/api/healthz_service_api.py", line 63, in get_healthz
    return self.get_healthz_with_http_info(**kwargs)  # noqa: E501
  File "/home/linuxbrew/.linuxbrew/opt/python@3.10/lib/python3.10/site-packages/kfp_server_api/api/healthz_service_api.py", line 134, in get_healthz_with_http_info
    return self.api_client.call_api(
  File "/home/linuxbrew/.linuxbrew/opt/python@3.10/lib/python3.10/site-packages/kfp_server_api/api_client.py", line 364, in call_api
    return self.__call_api(resource_path, method,
  File "/home/linuxbrew/.linuxbrew/opt/python@3.10/lib/python3.10/site-packages/kfp_server_api/api_client.py", line 188, in __call_api
    raise e
  File "/home/linuxbrew/.linuxbrew/opt/python@3.10/lib/python3.10/site-packages/kfp_server_api/api_client.py", line 181, in __call_api
    response_data = self.request(
  File "/home/linuxbrew/.linuxbrew/opt/python@3.10/lib/python3.10/site-packages/kfp_server_api/api_client.py", line 389, in request
    return self.rest_client.GET(url,
  File "/home/linuxbrew/.linuxbrew/opt/python@3.10/lib/python3.10/site-packages/kfp_server_api/rest.py", line 230, in GET
    return self.request("GET", url,
  File "/home/linuxbrew/.linuxbrew/opt/python@3.10/lib/python3.10/site-packages/kfp_server_api/rest.py", line 224, in request
    raise ApiException(http_resp=r)
kfp_server_api.exceptions.ApiException: (524)
Reason: status code 524
HTTP response headers: HTTPHeaderDict({'Content-Length': '1440', 'Content-Type': 'text/html; charset=utf-8', 'Date': 'Wed, 07 Sep 2022 16:57:28 GMT', 'Vary': 'Origin', 'X-Content-Type-Options': 'nosniff', 'X-Frame-Options': 'SAMEORIGIN', 'X-Xss-Protection': '0', 'Set-Cookie': 'S=cloud_datalab_tunnel=AhUMZyywos2t016IR5Pokb5rfUEY6gmHqXuUa-BLTs4; Path=/; Max-Age=3600', 'Alt-Svc': 'h3=":443"; ma=2592000,h3-29=":443"; ma=2592000,h3-Q050=":443"; ma=2592000,h3-Q046=":443"; ma=2592000,h3-Q043=":443"; ma=2592000,quic=":443"; ma=2592000; v="46,43"'})
HTTP response body: 
<!DOCTYPE html>
<html lang=en>
  <meta charset=utf-8>
  <meta name=viewport content="initial-scale=1, minimum-scale=1, width=device-width">
  <title>Error 524 ()!!1</title>
  <style>
    *{margin:0;padding:0}html,code{font:15px/22px arial,sans-serif}html{background:#fff;color:#222;padding:15px}body{margin:7% auto 0;max-width:390px;min-height:180px;padding:30px 0 15px}* > body{background:url(//www.google.com/images/errors/robot.png) 100% 5px no-repeat;padding-right:205px}p{margin:11px 0 22px;overflow:hidden}ins{color:#777;text-decoration:none}a img{border:0}@media screen and (max-width:772px){body{background:none;margin-top:0;max-width:none;padding-right:0}}#logo{background:url(//www.google.com/images/logos/errorpage/error_logo-150x54.png) no-repeat;margin-left:-5px}@media only screen and (min-resolution:192dpi){#logo{background:url(//www.google.com/images/logos/errorpage/error_logo-150x54-2x.png) no-repeat 0% 0%/100% 100%;-moz-border-image:url(//www.google.com/images/logos/errorpage/error_logo-150x54-2x.png) 0}}@media only screen and (-webkit-min-device-pixel-ratio:2){#logo{background:url(//www.google.com/images/logos/errorpage/error_logo-150x54-2x.png) no-repeat;-webkit-background-size:100% 100%}}#logo{display:inline-block;height:54px;width:150px}
  </style>
  <a href=//www.google.com/><span id=logo aria-label=Google></span></a>
  <p><b>524.</b> <ins>That’s an error.</ins>
  <p>  <ins>That’s all we know.</ins>


2022-09-07 10:59:33,990 - root - ERROR - Failed to get healthz info attempt 3 of 5.
Traceback (most recent call last):
  File "/home/linuxbrew/.linuxbrew/opt/python@3.10/lib/python3.10/site-packages/kfp/_client.py", line 411, in get_kfp_healthz
    response = self._healthz_api.get_healthz()
  File "/home/linuxbrew/.linuxbrew/opt/python@3.10/lib/python3.10/site-packages/kfp_server_api/api/healthz_service_api.py", line 63, in get_healthz
    return self.get_healthz_with_http_info(**kwargs)  # noqa: E501
  File "/home/linuxbrew/.linuxbrew/opt/python@3.10/lib/python3.10/site-packages/kfp_server_api/api/healthz_service_api.py", line 134, in get_healthz_with_http_info
    return self.api_client.call_api(
  File "/home/linuxbrew/.linuxbrew/opt/python@3.10/lib/python3.10/site-packages/kfp_server_api/api_client.py", line 364, in call_api
    return self.__call_api(resource_path, method,
  File "/home/linuxbrew/.linuxbrew/opt/python@3.10/lib/python3.10/site-packages/kfp_server_api/api_client.py", line 188, in __call_api
    raise e
  File "/home/linuxbrew/.linuxbrew/opt/python@3.10/lib/python3.10/site-packages/kfp_server_api/api_client.py", line 181, in __call_api
    response_data = self.request(
  File "/home/linuxbrew/.linuxbrew/opt/python@3.10/lib/python3.10/site-packages/kfp_server_api/api_client.py", line 389, in request
    return self.rest_client.GET(url,
  File "/home/linuxbrew/.linuxbrew/opt/python@3.10/lib/python3.10/site-packages/kfp_server_api/rest.py", line 230, in GET
    return self.request("GET", url,
  File "/home/linuxbrew/.linuxbrew/opt/python@3.10/lib/python3.10/site-packages/kfp_server_api/rest.py", line 224, in request
    raise ApiException(http_resp=r)
kfp_server_api.exceptions.ApiException: (524)
Reason: status code 524
HTTP response headers: HTTPHeaderDict({'Content-Length': '1440', 'Content-Type': 'text/html; charset=utf-8', 'Date': 'Wed, 07 Sep 2022 16:59:34 GMT', 'Vary': 'Origin', 'X-Content-Type-Options': 'nosniff', 'X-Frame-Options': 'SAMEORIGIN', 'X-Xss-Protection': '0', 'Set-Cookie': 'S=cloud_datalab_tunnel=AhUMZyywos2t016IR5Pokb5rfUEY6gmHqXuUa-BLTs4; Path=/; Max-Age=3600', 'Alt-Svc': 'h3=":443"; ma=2592000,h3-29=":443"; ma=2592000,h3-Q050=":443"; ma=2592000,h3-Q046=":443"; ma=2592000,h3-Q043=":443"; ma=2592000,quic=":443"; ma=2592000; v="46,43"'})
HTTP response body: 
<!DOCTYPE html>
<html lang=en>
  <meta charset=utf-8>
  <meta name=viewport content="initial-scale=1, minimum-scale=1, width=device-width">
  <title>Error 524 ()!!1</title>
  <style>
    *{margin:0;padding:0}html,code{font:15px/22px arial,sans-serif}html{background:#fff;color:#222;padding:15px}body{margin:7% auto 0;max-width:390px;min-height:180px;padding:30px 0 15px}* > body{background:url(//www.google.com/images/errors/robot.png) 100% 5px no-repeat;padding-right:205px}p{margin:11px 0 22px;overflow:hidden}ins{color:#777;text-decoration:none}a img{border:0}@media screen and (max-width:772px){body{background:none;margin-top:0;max-width:none;padding-right:0}}#logo{background:url(//www.google.com/images/logos/errorpage/error_logo-150x54.png) no-repeat;margin-left:-5px}@media only screen and (min-resolution:192dpi){#logo{background:url(//www.google.com/images/logos/errorpage/error_logo-150x54-2x.png) no-repeat 0% 0%/100% 100%;-moz-border-image:url(//www.google.com/images/logos/errorpage/error_logo-150x54-2x.png) 0}}@media only screen and (-webkit-min-device-pixel-ratio:2){#logo{background:url(//www.google.com/images/logos/errorpage/error_logo-150x54-2x.png) no-repeat;-webkit-background-size:100% 100%}}#logo{display:inline-block;height:54px;width:150px}
  </style>
  <a href=//www.google.com/><span id=logo aria-label=Google></span></a>
  <p><b>524.</b> <ins>That’s an error.</ins>
  <p>  <ins>That’s all we know.</ins>


2022-09-07 11:01:39,459 - root - ERROR - Failed to get healthz info attempt 4 of 5.
Traceback (most recent call last):
  File "/home/linuxbrew/.linuxbrew/opt/python@3.10/lib/python3.10/site-packages/kfp/_client.py", line 411, in get_kfp_healthz
    response = self._healthz_api.get_healthz()
  File "/home/linuxbrew/.linuxbrew/opt/python@3.10/lib/python3.10/site-packages/kfp_server_api/api/healthz_service_api.py", line 63, in get_healthz
    return self.get_healthz_with_http_info(**kwargs)  # noqa: E501
  File "/home/linuxbrew/.linuxbrew/opt/python@3.10/lib/python3.10/site-packages/kfp_server_api/api/healthz_service_api.py", line 134, in get_healthz_with_http_info
    return self.api_client.call_api(
  File "/home/linuxbrew/.linuxbrew/opt/python@3.10/lib/python3.10/site-packages/kfp_server_api/api_client.py", line 364, in call_api
    return self.__call_api(resource_path, method,
  File "/home/linuxbrew/.linuxbrew/opt/python@3.10/lib/python3.10/site-packages/kfp_server_api/api_client.py", line 188, in __call_api
    raise e
  File "/home/linuxbrew/.linuxbrew/opt/python@3.10/lib/python3.10/site-packages/kfp_server_api/api_client.py", line 181, in __call_api
    response_data = self.request(
  File "/home/linuxbrew/.linuxbrew/opt/python@3.10/lib/python3.10/site-packages/kfp_server_api/api_client.py", line 389, in request
    return self.rest_client.GET(url,
  File "/home/linuxbrew/.linuxbrew/opt/python@3.10/lib/python3.10/site-packages/kfp_server_api/rest.py", line 230, in GET
    return self.request("GET", url,
  File "/home/linuxbrew/.linuxbrew/opt/python@3.10/lib/python3.10/site-packages/kfp_server_api/rest.py", line 224, in request
    raise ApiException(http_resp=r)
kfp_server_api.exceptions.ApiException: (524)
Reason: status code 524
HTTP response headers: HTTPHeaderDict({'Content-Length': '1440', 'Content-Type': 'text/html; charset=utf-8', 'Date': 'Wed, 07 Sep 2022 17:01:39 GMT', 'Vary': 'Origin', 'X-Content-Type-Options': 'nosniff', 'X-Frame-Options': 'SAMEORIGIN', 'X-Xss-Protection': '0', 'Set-Cookie': 'S=cloud_datalab_tunnel=AhUMZyywos2t016IR5Pokb5rfUEY6gmHqXuUa-BLTs4; Path=/; Max-Age=3600', 'Alt-Svc': 'h3=":443"; ma=2592000,h3-29=":443"; ma=2592000,h3-Q050=":443"; ma=2592000,h3-Q046=":443"; ma=2592000,h3-Q043=":443"; ma=2592000,quic=":443"; ma=2592000; v="46,43"'})
HTTP response body: 
<!DOCTYPE html>
<html lang=en>
  <meta charset=utf-8>
  <meta name=viewport content="initial-scale=1, minimum-scale=1, width=device-width">
  <title>Error 524 ()!!1</title>
  <style>
    *{margin:0;padding:0}html,code{font:15px/22px arial,sans-serif}html{background:#fff;color:#222;padding:15px}body{margin:7% auto 0;max-width:390px;min-height:180px;padding:30px 0 15px}* > body{background:url(//www.google.com/images/errors/robot.png) 100% 5px no-repeat;padding-right:205px}p{margin:11px 0 22px;overflow:hidden}ins{color:#777;text-decoration:none}a img{border:0}@media screen and (max-width:772px){body{background:none;margin-top:0;max-width:none;padding-right:0}}#logo{background:url(//www.google.com/images/logos/errorpage/error_logo-150x54.png) no-repeat;margin-left:-5px}@media only screen and (min-resolution:192dpi){#logo{background:url(//www.google.com/images/logos/errorpage/error_logo-150x54-2x.png) no-repeat 0% 0%/100% 100%;-moz-border-image:url(//www.google.com/images/logos/errorpage/error_logo-150x54-2x.png) 0}}@media only screen and (-webkit-min-device-pixel-ratio:2){#logo{background:url(//www.google.com/images/logos/errorpage/error_logo-150x54-2x.png) no-repeat;-webkit-background-size:100% 100%}}#logo{display:inline-block;height:54px;width:150px}
  </style>
  <a href=//www.google.com/><span id=logo aria-label=Google></span></a>
  <p><b>524.</b> <ins>That’s an error.</ins>
  <p>  <ins>That’s all we know.</ins>


2022-09-07 11:03:44,732 - root - ERROR - Failed to get healthz info attempt 5 of 5.
Traceback (most recent call last):
  File "/home/linuxbrew/.linuxbrew/opt/python@3.10/lib/python3.10/site-packages/kfp/_client.py", line 411, in get_kfp_healthz
    response = self._healthz_api.get_healthz()
  File "/home/linuxbrew/.linuxbrew/opt/python@3.10/lib/python3.10/site-packages/kfp_server_api/api/healthz_service_api.py", line 63, in get_healthz
    return self.get_healthz_with_http_info(**kwargs)  # noqa: E501
  File "/home/linuxbrew/.linuxbrew/opt/python@3.10/lib/python3.10/site-packages/kfp_server_api/api/healthz_service_api.py", line 134, in get_healthz_with_http_info
    return self.api_client.call_api(
  File "/home/linuxbrew/.linuxbrew/opt/python@3.10/lib/python3.10/site-packages/kfp_server_api/api_client.py", line 364, in call_api
    return self.__call_api(resource_path, method,
  File "/home/linuxbrew/.linuxbrew/opt/python@3.10/lib/python3.10/site-packages/kfp_server_api/api_client.py", line 188, in __call_api
    raise e
  File "/home/linuxbrew/.linuxbrew/opt/python@3.10/lib/python3.10/site-packages/kfp_server_api/api_client.py", line 181, in __call_api
    response_data = self.request(
  File "/home/linuxbrew/.linuxbrew/opt/python@3.10/lib/python3.10/site-packages/kfp_server_api/api_client.py", line 389, in request
    return self.rest_client.GET(url,
  File "/home/linuxbrew/.linuxbrew/opt/python@3.10/lib/python3.10/site-packages/kfp_server_api/rest.py", line 230, in GET
    return self.request("GET", url,
  File "/home/linuxbrew/.linuxbrew/opt/python@3.10/lib/python3.10/site-packages/kfp_server_api/rest.py", line 224, in request
    raise ApiException(http_resp=r)
kfp_server_api.exceptions.ApiException: (524)
Reason: status code 524
HTTP response headers: HTTPHeaderDict({'Content-Length': '1440', 'Content-Type': 'text/html; charset=utf-8', 'Date': 'Wed, 07 Sep 2022 17:03:45 GMT', 'Vary': 'Origin', 'X-Content-Type-Options': 'nosniff', 'X-Frame-Options': 'SAMEORIGIN', 'X-Xss-Protection': '0', 'Set-Cookie': 'S=cloud_datalab_tunnel=AhUMZyywos2t016IR5Pokb5rfUEY6gmHqXuUa-BLTs4; Path=/; Max-Age=3600', 'Alt-Svc': 'h3=":443"; ma=2592000,h3-29=":443"; ma=2592000,h3-Q050=":443"; ma=2592000,h3-Q046=":443"; ma=2592000,h3-Q043=":443"; ma=2592000,quic=":443"; ma=2592000; v="46,43"'})
HTTP response body: 
<!DOCTYPE html>
<html lang=en>
  <meta charset=utf-8>
  <meta name=viewport content="initial-scale=1, minimum-scale=1, width=device-width">
  <title>Error 524 ()!!1</title>
  <style>
    *{margin:0;padding:0}html,code{font:15px/22px arial,sans-serif}html{background:#fff;color:#222;padding:15px}body{margin:7% auto 0;max-width:390px;min-height:180px;padding:30px 0 15px}* > body{background:url(//www.google.com/images/errors/robot.png) 100% 5px no-repeat;padding-right:205px}p{margin:11px 0 22px;overflow:hidden}ins{color:#777;text-decoration:none}a img{border:0}@media screen and (max-width:772px){body{background:none;margin-top:0;max-width:none;padding-right:0}}#logo{background:url(//www.google.com/images/logos/errorpage/error_logo-150x54.png) no-repeat;margin-left:-5px}@media only screen and (min-resolution:192dpi){#logo{background:url(//www.google.com/images/logos/errorpage/error_logo-150x54-2x.png) no-repeat 0% 0%/100% 100%;-moz-border-image:url(//www.google.com/images/logos/errorpage/error_logo-150x54-2x.png) 0}}@media only screen and (-webkit-min-device-pixel-ratio:2){#logo{background:url(//www.google.com/images/logos/errorpage/error_logo-150x54-2x.png) no-repeat;-webkit-background-size:100% 100%}}#logo{display:inline-block;height:54px;width:150px}
  </style>
  <a href=//www.google.com/><span id=logo aria-label=Google></span></a>
  <p><b>524.</b> <ins>That’s an error.</ins>
  <p>  <ins>That’s all we know.</ins>


2022-09-07 11:37:09,231 - py.warnings - WARNING - /home/linuxbrew/.linuxbrew/opt/python@3.10/lib/python3.10/site-packages/google/auth/_default.py:70: UserWarning: Your application has authenticated using end user credentials from Google Cloud SDK without a quota project. You might receive a "quota exceeded" or "API not enabled" error. We recommend you rerun `gcloud auth application-default login` and make sure a quota project is added. Or you can use service accounts instead. For more information about service accounts, see https://cloud.google.com/docs/authentication/
  warnings.warn(_CLOUD_SDK_CREDENTIALS_WARNING)

2022-09-07 11:39:10,900 - root - ERROR - Failed to get healthz info attempt 1 of 5.
Traceback (most recent call last):
  File "/home/linuxbrew/.linuxbrew/opt/python@3.10/lib/python3.10/site-packages/kfp/_client.py", line 411, in get_kfp_healthz
    response = self._healthz_api.get_healthz()
  File "/home/linuxbrew/.linuxbrew/opt/python@3.10/lib/python3.10/site-packages/kfp_server_api/api/healthz_service_api.py", line 63, in get_healthz
    return self.get_healthz_with_http_info(**kwargs)  # noqa: E501
  File "/home/linuxbrew/.linuxbrew/opt/python@3.10/lib/python3.10/site-packages/kfp_server_api/api/healthz_service_api.py", line 134, in get_healthz_with_http_info
    return self.api_client.call_api(
  File "/home/linuxbrew/.linuxbrew/opt/python@3.10/lib/python3.10/site-packages/kfp_server_api/api_client.py", line 364, in call_api
    return self.__call_api(resource_path, method,
  File "/home/linuxbrew/.linuxbrew/opt/python@3.10/lib/python3.10/site-packages/kfp_server_api/api_client.py", line 188, in __call_api
    raise e
  File "/home/linuxbrew/.linuxbrew/opt/python@3.10/lib/python3.10/site-packages/kfp_server_api/api_client.py", line 181, in __call_api
    response_data = self.request(
  File "/home/linuxbrew/.linuxbrew/opt/python@3.10/lib/python3.10/site-packages/kfp_server_api/api_client.py", line 389, in request
    return self.rest_client.GET(url,
  File "/home/linuxbrew/.linuxbrew/opt/python@3.10/lib/python3.10/site-packages/kfp_server_api/rest.py", line 230, in GET
    return self.request("GET", url,
  File "/home/linuxbrew/.linuxbrew/opt/python@3.10/lib/python3.10/site-packages/kfp_server_api/rest.py", line 224, in request
    raise ApiException(http_resp=r)
kfp_server_api.exceptions.ApiException: (524)
Reason: status code 524
HTTP response headers: HTTPHeaderDict({'Content-Length': '1440', 'Content-Type': 'text/html; charset=utf-8', 'Date': 'Wed, 07 Sep 2022 17:39:11 GMT', 'Vary': 'Origin', 'X-Content-Type-Options': 'nosniff', 'X-Frame-Options': 'SAMEORIGIN', 'X-Xss-Protection': '0', 'Set-Cookie': 'S=cloud_datalab_tunnel=AhUMZyywos2t016IR5Pokb5rfUEY6gmHqXuUa-BLTs4; Path=/; Max-Age=3600', 'Alt-Svc': 'h3=":443"; ma=2592000,h3-29=":443"; ma=2592000,h3-Q050=":443"; ma=2592000,h3-Q046=":443"; ma=2592000,h3-Q043=":443"; ma=2592000,quic=":443"; ma=2592000; v="46,43"'})
HTTP response body: 
<!DOCTYPE html>
<html lang=en>
  <meta charset=utf-8>
  <meta name=viewport content="initial-scale=1, minimum-scale=1, width=device-width">
  <title>Error 524 ()!!1</title>
  <style>
    *{margin:0;padding:0}html,code{font:15px/22px arial,sans-serif}html{background:#fff;color:#222;padding:15px}body{margin:7% auto 0;max-width:390px;min-height:180px;padding:30px 0 15px}* > body{background:url(//www.google.com/images/errors/robot.png) 100% 5px no-repeat;padding-right:205px}p{margin:11px 0 22px;overflow:hidden}ins{color:#777;text-decoration:none}a img{border:0}@media screen and (max-width:772px){body{background:none;margin-top:0;max-width:none;padding-right:0}}#logo{background:url(//www.google.com/images/logos/errorpage/error_logo-150x54.png) no-repeat;margin-left:-5px}@media only screen and (min-resolution:192dpi){#logo{background:url(//www.google.com/images/logos/errorpage/error_logo-150x54-2x.png) no-repeat 0% 0%/100% 100%;-moz-border-image:url(//www.google.com/images/logos/errorpage/error_logo-150x54-2x.png) 0}}@media only screen and (-webkit-min-device-pixel-ratio:2){#logo{background:url(//www.google.com/images/logos/errorpage/error_logo-150x54-2x.png) no-repeat;-webkit-background-size:100% 100%}}#logo{display:inline-block;height:54px;width:150px}
  </style>
  <a href=//www.google.com/><span id=logo aria-label=Google></span></a>
  <p><b>524.</b> <ins>That’s an error.</ins>
  <p>  <ins>That’s all we know.</ins>


2022-09-07 11:41:16,328 - root - ERROR - Failed to get healthz info attempt 2 of 5.
Traceback (most recent call last):
  File "/home/linuxbrew/.linuxbrew/opt/python@3.10/lib/python3.10/site-packages/kfp/_client.py", line 411, in get_kfp_healthz
    response = self._healthz_api.get_healthz()
  File "/home/linuxbrew/.linuxbrew/opt/python@3.10/lib/python3.10/site-packages/kfp_server_api/api/healthz_service_api.py", line 63, in get_healthz
    return self.get_healthz_with_http_info(**kwargs)  # noqa: E501
  File "/home/linuxbrew/.linuxbrew/opt/python@3.10/lib/python3.10/site-packages/kfp_server_api/api/healthz_service_api.py", line 134, in get_healthz_with_http_info
    return self.api_client.call_api(
  File "/home/linuxbrew/.linuxbrew/opt/python@3.10/lib/python3.10/site-packages/kfp_server_api/api_client.py", line 364, in call_api
    return self.__call_api(resource_path, method,
  File "/home/linuxbrew/.linuxbrew/opt/python@3.10/lib/python3.10/site-packages/kfp_server_api/api_client.py", line 188, in __call_api
    raise e
  File "/home/linuxbrew/.linuxbrew/opt/python@3.10/lib/python3.10/site-packages/kfp_server_api/api_client.py", line 181, in __call_api
    response_data = self.request(
  File "/home/linuxbrew/.linuxbrew/opt/python@3.10/lib/python3.10/site-packages/kfp_server_api/api_client.py", line 389, in request
    return self.rest_client.GET(url,
  File "/home/linuxbrew/.linuxbrew/opt/python@3.10/lib/python3.10/site-packages/kfp_server_api/rest.py", line 230, in GET
    return self.request("GET", url,
  File "/home/linuxbrew/.linuxbrew/opt/python@3.10/lib/python3.10/site-packages/kfp_server_api/rest.py", line 224, in request
    raise ApiException(http_resp=r)
kfp_server_api.exceptions.ApiException: (524)
Reason: status code 524
HTTP response headers: HTTPHeaderDict({'Content-Length': '1440', 'Content-Type': 'text/html; charset=utf-8', 'Date': 'Wed, 07 Sep 2022 17:41:16 GMT', 'Vary': 'Origin', 'X-Content-Type-Options': 'nosniff', 'X-Frame-Options': 'SAMEORIGIN', 'X-Xss-Protection': '0', 'Set-Cookie': 'S=cloud_datalab_tunnel=AhUMZyywos2t016IR5Pokb5rfUEY6gmHqXuUa-BLTs4; Path=/; Max-Age=3600', 'Alt-Svc': 'h3=":443"; ma=2592000,h3-29=":443"; ma=2592000,h3-Q050=":443"; ma=2592000,h3-Q046=":443"; ma=2592000,h3-Q043=":443"; ma=2592000,quic=":443"; ma=2592000; v="46,43"'})
HTTP response body: 
<!DOCTYPE html>
<html lang=en>
  <meta charset=utf-8>
  <meta name=viewport content="initial-scale=1, minimum-scale=1, width=device-width">
  <title>Error 524 ()!!1</title>
  <style>
    *{margin:0;padding:0}html,code{font:15px/22px arial,sans-serif}html{background:#fff;color:#222;padding:15px}body{margin:7% auto 0;max-width:390px;min-height:180px;padding:30px 0 15px}* > body{background:url(//www.google.com/images/errors/robot.png) 100% 5px no-repeat;padding-right:205px}p{margin:11px 0 22px;overflow:hidden}ins{color:#777;text-decoration:none}a img{border:0}@media screen and (max-width:772px){body{background:none;margin-top:0;max-width:none;padding-right:0}}#logo{background:url(//www.google.com/images/logos/errorpage/error_logo-150x54.png) no-repeat;margin-left:-5px}@media only screen and (min-resolution:192dpi){#logo{background:url(//www.google.com/images/logos/errorpage/error_logo-150x54-2x.png) no-repeat 0% 0%/100% 100%;-moz-border-image:url(//www.google.com/images/logos/errorpage/error_logo-150x54-2x.png) 0}}@media only screen and (-webkit-min-device-pixel-ratio:2){#logo{background:url(//www.google.com/images/logos/errorpage/error_logo-150x54-2x.png) no-repeat;-webkit-background-size:100% 100%}}#logo{display:inline-block;height:54px;width:150px}
  </style>
  <a href=//www.google.com/><span id=logo aria-label=Google></span></a>
  <p><b>524.</b> <ins>That’s an error.</ins>
  <p>  <ins>That’s all we know.</ins>


2022-09-07 11:43:21,604 - root - ERROR - Failed to get healthz info attempt 3 of 5.
Traceback (most recent call last):
  File "/home/linuxbrew/.linuxbrew/opt/python@3.10/lib/python3.10/site-packages/kfp/_client.py", line 411, in get_kfp_healthz
    response = self._healthz_api.get_healthz()
  File "/home/linuxbrew/.linuxbrew/opt/python@3.10/lib/python3.10/site-packages/kfp_server_api/api/healthz_service_api.py", line 63, in get_healthz
    return self.get_healthz_with_http_info(**kwargs)  # noqa: E501
  File "/home/linuxbrew/.linuxbrew/opt/python@3.10/lib/python3.10/site-packages/kfp_server_api/api/healthz_service_api.py", line 134, in get_healthz_with_http_info
    return self.api_client.call_api(
  File "/home/linuxbrew/.linuxbrew/opt/python@3.10/lib/python3.10/site-packages/kfp_server_api/api_client.py", line 364, in call_api
    return self.__call_api(resource_path, method,
  File "/home/linuxbrew/.linuxbrew/opt/python@3.10/lib/python3.10/site-packages/kfp_server_api/api_client.py", line 188, in __call_api
    raise e
  File "/home/linuxbrew/.linuxbrew/opt/python@3.10/lib/python3.10/site-packages/kfp_server_api/api_client.py", line 181, in __call_api
    response_data = self.request(
  File "/home/linuxbrew/.linuxbrew/opt/python@3.10/lib/python3.10/site-packages/kfp_server_api/api_client.py", line 389, in request
    return self.rest_client.GET(url,
  File "/home/linuxbrew/.linuxbrew/opt/python@3.10/lib/python3.10/site-packages/kfp_server_api/rest.py", line 230, in GET
    return self.request("GET", url,
  File "/home/linuxbrew/.linuxbrew/opt/python@3.10/lib/python3.10/site-packages/kfp_server_api/rest.py", line 224, in request
    raise ApiException(http_resp=r)
kfp_server_api.exceptions.ApiException: (524)
Reason: status code 524
HTTP response headers: HTTPHeaderDict({'Content-Length': '1440', 'Content-Type': 'text/html; charset=utf-8', 'Date': 'Wed, 07 Sep 2022 17:43:21 GMT', 'Vary': 'Origin', 'X-Content-Type-Options': 'nosniff', 'X-Frame-Options': 'SAMEORIGIN', 'X-Xss-Protection': '0', 'Set-Cookie': 'S=cloud_datalab_tunnel=AhUMZyywos2t016IR5Pokb5rfUEY6gmHqXuUa-BLTs4; Path=/; Max-Age=3600', 'Alt-Svc': 'h3=":443"; ma=2592000,h3-29=":443"; ma=2592000,h3-Q050=":443"; ma=2592000,h3-Q046=":443"; ma=2592000,h3-Q043=":443"; ma=2592000,quic=":443"; ma=2592000; v="46,43"'})
HTTP response body: 
<!DOCTYPE html>
<html lang=en>
  <meta charset=utf-8>
  <meta name=viewport content="initial-scale=1, minimum-scale=1, width=device-width">
  <title>Error 524 ()!!1</title>
  <style>
    *{margin:0;padding:0}html,code{font:15px/22px arial,sans-serif}html{background:#fff;color:#222;padding:15px}body{margin:7% auto 0;max-width:390px;min-height:180px;padding:30px 0 15px}* > body{background:url(//www.google.com/images/errors/robot.png) 100% 5px no-repeat;padding-right:205px}p{margin:11px 0 22px;overflow:hidden}ins{color:#777;text-decoration:none}a img{border:0}@media screen and (max-width:772px){body{background:none;margin-top:0;max-width:none;padding-right:0}}#logo{background:url(//www.google.com/images/logos/errorpage/error_logo-150x54.png) no-repeat;margin-left:-5px}@media only screen and (min-resolution:192dpi){#logo{background:url(//www.google.com/images/logos/errorpage/error_logo-150x54-2x.png) no-repeat 0% 0%/100% 100%;-moz-border-image:url(//www.google.com/images/logos/errorpage/error_logo-150x54-2x.png) 0}}@media only screen and (-webkit-min-device-pixel-ratio:2){#logo{background:url(//www.google.com/images/logos/errorpage/error_logo-150x54-2x.png) no-repeat;-webkit-background-size:100% 100%}}#logo{display:inline-block;height:54px;width:150px}
  </style>
  <a href=//www.google.com/><span id=logo aria-label=Google></span></a>
  <p><b>524.</b> <ins>That’s an error.</ins>
  <p>  <ins>That’s all we know.</ins>


2022-09-07 11:45:26,964 - root - ERROR - Failed to get healthz info attempt 4 of 5.
Traceback (most recent call last):
  File "/home/linuxbrew/.linuxbrew/opt/python@3.10/lib/python3.10/site-packages/kfp/_client.py", line 411, in get_kfp_healthz
    response = self._healthz_api.get_healthz()
  File "/home/linuxbrew/.linuxbrew/opt/python@3.10/lib/python3.10/site-packages/kfp_server_api/api/healthz_service_api.py", line 63, in get_healthz
    return self.get_healthz_with_http_info(**kwargs)  # noqa: E501
  File "/home/linuxbrew/.linuxbrew/opt/python@3.10/lib/python3.10/site-packages/kfp_server_api/api/healthz_service_api.py", line 134, in get_healthz_with_http_info
    return self.api_client.call_api(
  File "/home/linuxbrew/.linuxbrew/opt/python@3.10/lib/python3.10/site-packages/kfp_server_api/api_client.py", line 364, in call_api
    return self.__call_api(resource_path, method,
  File "/home/linuxbrew/.linuxbrew/opt/python@3.10/lib/python3.10/site-packages/kfp_server_api/api_client.py", line 188, in __call_api
    raise e
  File "/home/linuxbrew/.linuxbrew/opt/python@3.10/lib/python3.10/site-packages/kfp_server_api/api_client.py", line 181, in __call_api
    response_data = self.request(
  File "/home/linuxbrew/.linuxbrew/opt/python@3.10/lib/python3.10/site-packages/kfp_server_api/api_client.py", line 389, in request
    return self.rest_client.GET(url,
  File "/home/linuxbrew/.linuxbrew/opt/python@3.10/lib/python3.10/site-packages/kfp_server_api/rest.py", line 230, in GET
    return self.request("GET", url,
  File "/home/linuxbrew/.linuxbrew/opt/python@3.10/lib/python3.10/site-packages/kfp_server_api/rest.py", line 224, in request
    raise ApiException(http_resp=r)
kfp_server_api.exceptions.ApiException: (524)
Reason: status code 524
HTTP response headers: HTTPHeaderDict({'Content-Length': '1440', 'Content-Type': 'text/html; charset=utf-8', 'Date': 'Wed, 07 Sep 2022 17:45:27 GMT', 'Vary': 'Origin', 'X-Content-Type-Options': 'nosniff', 'X-Frame-Options': 'SAMEORIGIN', 'X-Xss-Protection': '0', 'Set-Cookie': 'S=cloud_datalab_tunnel=AhUMZyywos2t016IR5Pokb5rfUEY6gmHqXuUa-BLTs4; Path=/; Max-Age=3600', 'Alt-Svc': 'h3=":443"; ma=2592000,h3-29=":443"; ma=2592000,h3-Q050=":443"; ma=2592000,h3-Q046=":443"; ma=2592000,h3-Q043=":443"; ma=2592000,quic=":443"; ma=2592000; v="46,43"'})
HTTP response body: 
<!DOCTYPE html>
<html lang=en>
  <meta charset=utf-8>
  <meta name=viewport content="initial-scale=1, minimum-scale=1, width=device-width">
  <title>Error 524 ()!!1</title>
  <style>
    *{margin:0;padding:0}html,code{font:15px/22px arial,sans-serif}html{background:#fff;color:#222;padding:15px}body{margin:7% auto 0;max-width:390px;min-height:180px;padding:30px 0 15px}* > body{background:url(//www.google.com/images/errors/robot.png) 100% 5px no-repeat;padding-right:205px}p{margin:11px 0 22px;overflow:hidden}ins{color:#777;text-decoration:none}a img{border:0}@media screen and (max-width:772px){body{background:none;margin-top:0;max-width:none;padding-right:0}}#logo{background:url(//www.google.com/images/logos/errorpage/error_logo-150x54.png) no-repeat;margin-left:-5px}@media only screen and (min-resolution:192dpi){#logo{background:url(//www.google.com/images/logos/errorpage/error_logo-150x54-2x.png) no-repeat 0% 0%/100% 100%;-moz-border-image:url(//www.google.com/images/logos/errorpage/error_logo-150x54-2x.png) 0}}@media only screen and (-webkit-min-device-pixel-ratio:2){#logo{background:url(//www.google.com/images/logos/errorpage/error_logo-150x54-2x.png) no-repeat;-webkit-background-size:100% 100%}}#logo{display:inline-block;height:54px;width:150px}
  </style>
  <a href=//www.google.com/><span id=logo aria-label=Google></span></a>
  <p><b>524.</b> <ins>That’s an error.</ins>
  <p>  <ins>That’s all we know.</ins>


2022-09-07 11:47:32,272 - root - ERROR - Failed to get healthz info attempt 5 of 5.
Traceback (most recent call last):
  File "/home/linuxbrew/.linuxbrew/opt/python@3.10/lib/python3.10/site-packages/kfp/_client.py", line 411, in get_kfp_healthz
    response = self._healthz_api.get_healthz()
  File "/home/linuxbrew/.linuxbrew/opt/python@3.10/lib/python3.10/site-packages/kfp_server_api/api/healthz_service_api.py", line 63, in get_healthz
    return self.get_healthz_with_http_info(**kwargs)  # noqa: E501
  File "/home/linuxbrew/.linuxbrew/opt/python@3.10/lib/python3.10/site-packages/kfp_server_api/api/healthz_service_api.py", line 134, in get_healthz_with_http_info
    return self.api_client.call_api(
  File "/home/linuxbrew/.linuxbrew/opt/python@3.10/lib/python3.10/site-packages/kfp_server_api/api_client.py", line 364, in call_api
    return self.__call_api(resource_path, method,
  File "/home/linuxbrew/.linuxbrew/opt/python@3.10/lib/python3.10/site-packages/kfp_server_api/api_client.py", line 188, in __call_api
    raise e
  File "/home/linuxbrew/.linuxbrew/opt/python@3.10/lib/python3.10/site-packages/kfp_server_api/api_client.py", line 181, in __call_api
    response_data = self.request(
  File "/home/linuxbrew/.linuxbrew/opt/python@3.10/lib/python3.10/site-packages/kfp_server_api/api_client.py", line 389, in request
    return self.rest_client.GET(url,
  File "/home/linuxbrew/.linuxbrew/opt/python@3.10/lib/python3.10/site-packages/kfp_server_api/rest.py", line 230, in GET
    return self.request("GET", url,
  File "/home/linuxbrew/.linuxbrew/opt/python@3.10/lib/python3.10/site-packages/kfp_server_api/rest.py", line 224, in request
    raise ApiException(http_resp=r)
kfp_server_api.exceptions.ApiException: (524)
Reason: status code 524
HTTP response headers: HTTPHeaderDict({'Content-Length': '1440', 'Content-Type': 'text/html; charset=utf-8', 'Date': 'Wed, 07 Sep 2022 17:47:32 GMT', 'Vary': 'Origin', 'X-Content-Type-Options': 'nosniff', 'X-Frame-Options': 'SAMEORIGIN', 'X-Xss-Protection': '0', 'Set-Cookie': 'S=cloud_datalab_tunnel=AhUMZyywos2t016IR5Pokb5rfUEY6gmHqXuUa-BLTs4; Path=/; Max-Age=3600', 'Alt-Svc': 'h3=":443"; ma=2592000,h3-29=":443"; ma=2592000,h3-Q050=":443"; ma=2592000,h3-Q046=":443"; ma=2592000,h3-Q043=":443"; ma=2592000,quic=":443"; ma=2592000; v="46,43"'})
HTTP response body: 
<!DOCTYPE html>
<html lang=en>
  <meta charset=utf-8>
  <meta name=viewport content="initial-scale=1, minimum-scale=1, width=device-width">
  <title>Error 524 ()!!1</title>
  <style>
    *{margin:0;padding:0}html,code{font:15px/22px arial,sans-serif}html{background:#fff;color:#222;padding:15px}body{margin:7% auto 0;max-width:390px;min-height:180px;padding:30px 0 15px}* > body{background:url(//www.google.com/images/errors/robot.png) 100% 5px no-repeat;padding-right:205px}p{margin:11px 0 22px;overflow:hidden}ins{color:#777;text-decoration:none}a img{border:0}@media screen and (max-width:772px){body{background:none;margin-top:0;max-width:none;padding-right:0}}#logo{background:url(//www.google.com/images/logos/errorpage/error_logo-150x54.png) no-repeat;margin-left:-5px}@media only screen and (min-resolution:192dpi){#logo{background:url(//www.google.com/images/logos/errorpage/error_logo-150x54-2x.png) no-repeat 0% 0%/100% 100%;-moz-border-image:url(//www.google.com/images/logos/errorpage/error_logo-150x54-2x.png) 0}}@media only screen and (-webkit-min-device-pixel-ratio:2){#logo{background:url(//www.google.com/images/logos/errorpage/error_logo-150x54-2x.png) no-repeat;-webkit-background-size:100% 100%}}#logo{display:inline-block;height:54px;width:150px}
  </style>
  <a href=//www.google.com/><span id=logo aria-label=Google></span></a>
  <p><b>524.</b> <ins>That’s an error.</ins>
  <p>  <ins>That’s all we know.</ins>


2022-09-08 10:12:24,563 - py.warnings - WARNING - /home/linuxbrew/.linuxbrew/opt/python@3.10/lib/python3.10/site-packages/google/auth/_default.py:70: UserWarning: Your application has authenticated using end user credentials from Google Cloud SDK without a quota project. You might receive a "quota exceeded" or "API not enabled" error. We recommend you rerun `gcloud auth application-default login` and make sure a quota project is added. Or you can use service accounts instead. For more information about service accounts, see https://cloud.google.com/docs/authentication/
  warnings.warn(_CLOUD_SDK_CREDENTIALS_WARNING)

2022-09-08 10:12:37,200 - py.warnings - WARNING - /home/linuxbrew/.linuxbrew/opt/python@3.10/lib/python3.10/site-packages/kfp/components/_data_passing.py:227: UserWarning: Missing type name was inferred as "Float" based on the value "0.8".
  warnings.warn(

2022-09-08 10:12:37,202 - py.warnings - WARNING - /home/linuxbrew/.linuxbrew/opt/python@3.10/lib/python3.10/site-packages/kfp/components/_data_passing.py:227: UserWarning: Missing type name was inferred as "Integer" based on the value "3".
  warnings.warn(

2022-09-08 10:12:38,051 - py.warnings - WARNING - /home/linuxbrew/.linuxbrew/opt/python@3.10/lib/python3.10/site-packages/google/auth/_default.py:70: UserWarning: Your application has authenticated using end user credentials from Google Cloud SDK without a quota project. You might receive a "quota exceeded" or "API not enabled" error. We recommend you rerun `gcloud auth application-default login` and make sure a quota project is added. Or you can use service accounts instead. For more information about service accounts, see https://cloud.google.com/docs/authentication/
  warnings.warn(_CLOUD_SDK_CREDENTIALS_WARNING)

2022-09-08 10:12:40,283 - py.warnings - WARNING - /home/linuxbrew/.linuxbrew/opt/python@3.10/lib/python3.10/site-packages/google/auth/_default.py:70: UserWarning: Your application has authenticated using end user credentials from Google Cloud SDK without a quota project. You might receive a "quota exceeded" or "API not enabled" error. We recommend you rerun `gcloud auth application-default login` and make sure a quota project is added. Or you can use service accounts instead. For more information about service accounts, see https://cloud.google.com/docs/authentication/
  warnings.warn(_CLOUD_SDK_CREDENTIALS_WARNING)

2022-09-08 10:13:39,794 - py.warnings - WARNING - /home/linuxbrew/.linuxbrew/opt/python@3.10/lib/python3.10/site-packages/google/auth/_default.py:70: UserWarning: Your application has authenticated using end user credentials from Google Cloud SDK without a quota project. You might receive a "quota exceeded" or "API not enabled" error. We recommend you rerun `gcloud auth application-default login` and make sure a quota project is added. Or you can use service accounts instead. For more information about service accounts, see https://cloud.google.com/docs/authentication/
  warnings.warn(_CLOUD_SDK_CREDENTIALS_WARNING)

2022-09-08 10:13:41,491 - py.warnings - WARNING - /home/linuxbrew/.linuxbrew/opt/python@3.10/lib/python3.10/site-packages/kfp/components/_data_passing.py:227: UserWarning: Missing type name was inferred as "Float" based on the value "0.8".
  warnings.warn(

2022-09-08 10:13:41,493 - py.warnings - WARNING - /home/linuxbrew/.linuxbrew/opt/python@3.10/lib/python3.10/site-packages/kfp/components/_data_passing.py:227: UserWarning: Missing type name was inferred as "Integer" based on the value "3".
  warnings.warn(

2022-09-08 10:13:41,913 - py.warnings - WARNING - /home/linuxbrew/.linuxbrew/opt/python@3.10/lib/python3.10/site-packages/google/auth/_default.py:70: UserWarning: Your application has authenticated using end user credentials from Google Cloud SDK without a quota project. You might receive a "quota exceeded" or "API not enabled" error. We recommend you rerun `gcloud auth application-default login` and make sure a quota project is added. Or you can use service accounts instead. For more information about service accounts, see https://cloud.google.com/docs/authentication/
  warnings.warn(_CLOUD_SDK_CREDENTIALS_WARNING)

2022-09-08 10:46:42,387 - py.warnings - WARNING - /home/linuxbrew/.linuxbrew/opt/python@3.10/lib/python3.10/site-packages/google/auth/_default.py:70: UserWarning: Your application has authenticated using end user credentials from Google Cloud SDK without a quota project. You might receive a "quota exceeded" or "API not enabled" error. We recommend you rerun `gcloud auth application-default login` and make sure a quota project is added. Or you can use service accounts instead. For more information about service accounts, see https://cloud.google.com/docs/authentication/
  warnings.warn(_CLOUD_SDK_CREDENTIALS_WARNING)

2022-09-08 10:46:44,170 - py.warnings - WARNING - /home/linuxbrew/.linuxbrew/opt/python@3.10/lib/python3.10/site-packages/kfp/components/_data_passing.py:227: UserWarning: Missing type name was inferred as "Float" based on the value "0.8".
  warnings.warn(

2022-09-08 10:46:44,171 - py.warnings - WARNING - /home/linuxbrew/.linuxbrew/opt/python@3.10/lib/python3.10/site-packages/kfp/components/_data_passing.py:227: UserWarning: Missing type name was inferred as "Integer" based on the value "3".
  warnings.warn(

2022-09-08 10:46:44,632 - py.warnings - WARNING - /home/linuxbrew/.linuxbrew/opt/python@3.10/lib/python3.10/site-packages/google/auth/_default.py:70: UserWarning: Your application has authenticated using end user credentials from Google Cloud SDK without a quota project. You might receive a "quota exceeded" or "API not enabled" error. We recommend you rerun `gcloud auth application-default login` and make sure a quota project is added. Or you can use service accounts instead. For more information about service accounts, see https://cloud.google.com/docs/authentication/
  warnings.warn(_CLOUD_SDK_CREDENTIALS_WARNING)

2022-09-08 16:05:35,824 - py.warnings - WARNING - /home/linuxbrew/.linuxbrew/opt/python@3.10/lib/python3.10/site-packages/google/auth/_default.py:70: UserWarning: Your application has authenticated using end user credentials from Google Cloud SDK without a quota project. You might receive a "quota exceeded" or "API not enabled" error. We recommend you rerun `gcloud auth application-default login` and make sure a quota project is added. Or you can use service accounts instead. For more information about service accounts, see https://cloud.google.com/docs/authentication/
  warnings.warn(_CLOUD_SDK_CREDENTIALS_WARNING)

2022-09-08 16:05:37,734 - py.warnings - WARNING - /home/linuxbrew/.linuxbrew/opt/python@3.10/lib/python3.10/site-packages/kfp/components/_data_passing.py:227: UserWarning: Missing type name was inferred as "Float" based on the value "0.8".
  warnings.warn(

2022-09-08 16:05:37,735 - py.warnings - WARNING - /home/linuxbrew/.linuxbrew/opt/python@3.10/lib/python3.10/site-packages/kfp/components/_data_passing.py:227: UserWarning: Missing type name was inferred as "Integer" based on the value "3".
  warnings.warn(

2022-09-08 16:05:38,213 - py.warnings - WARNING - /home/linuxbrew/.linuxbrew/opt/python@3.10/lib/python3.10/site-packages/google/auth/_default.py:70: UserWarning: Your application has authenticated using end user credentials from Google Cloud SDK without a quota project. You might receive a "quota exceeded" or "API not enabled" error. We recommend you rerun `gcloud auth application-default login` and make sure a quota project is added. Or you can use service accounts instead. For more information about service accounts, see https://cloud.google.com/docs/authentication/
  warnings.warn(_CLOUD_SDK_CREDENTIALS_WARNING)

